Workbook

Sheet Summary
A1: RRC: TFAC | F1: Fiscal Pages
A3: SUMMARY: Current Non-Sponsored Funds | D3: Actual | E3: Actual | F3: Actual | G3: Period 14 | H3: Projected | I3: Budget
C4: Excluding Multi Year accounts | D4: 1999-00 | E4: 2000-01 | F4: 2001-02 | G4: 2002-03 | H4: 2003-04 | I4: 2004-05
A5: RESOURCES
A6: a | B6: Carry Forward | D6: =SUM('1003':'1856'!D6:D6) -> 21373682 | E6: =SUM('1003':'1856'!E6:E6) -> 29147376 | F6: =SUM('1003':'1856'!F6:F6) -> 25814385 | G6: =SUM('1003':'1856'!G6:G6) -> 14914175 | H6: =SUM('1003':'1856'!H6:H6) -> 20496235 | I6: =SUM('1003':'1856'!I6:I6) -> 23394375
B8: Current Revenue - Total Revenue by Fund
C9: 1003 UMT-GENERAL OPERATIONS & MAINT | D9: ='1003'!D25 -> 54634.09 | E9: ='1003'!E25 -> 78451.09 | F9: ='1003'!F25 -> 44454.2 | G9: ='1003'!G25 -> 44916.68 | H9: ='1003'!H25 -> 22000 | I9: =+'1003'!I25 -> 0
C10: 1043 UMT-INDIRECT COST RECOVERY | D10: ='1043'!D25 -> 17149795 | E10: ='1043'!E25 -> 18149795 | F10: ='1043'!F25 -> 20517114 | G10: ='1043'!G25 -> 22073880 | H10: ='1043'!H25 -> 22073880 | I10: =+'1043'!I25 -> 0
C11: 1166 UMT-FACILITIES MANAGEMENT | D11: ='1166'!D25 -> 45228806 | E11: ='1166'!E25 -> 48127280 | F11: ='1166'!F25 -> 52007806 | G11: ='1166'!G25 -> 64581218 | H11: ='1166'!H25 -> 71502464 | I11: =+'1166'!I25 -> 0
C12: 1198 UMT-OTHER UNRESTRICTED | D12: ='1198'!D25 -> 2295561 | E12: ='1198'!E25 -> 2413816.7 | F12: ='1198'!F25 -> 2700375 | G12: ='1198'!G25 -> 2906794 | H12: ='1198'!H25 -> 0 | I12: =+'1198'!I25 -> 0
C13: 1856 UMT-NS/U OF MN FOUNDATION | D13: ='1856'!D25 -> 5543.16 | E13: ='1856'!E25 -> 5013.73 | F13: ='1856'!F25 -> 2200 | G13: ='1856'!G25 -> 13150 | H13: ='1856'!H25 -> 16 | I13: =+'1856'!I25 -> 0
A14: b | C14: Total Revenues | D14: =SUM(D9:D13) -> 64734340 | E14: =SUM(E9:E13) -> 68774357 | F14: =SUM(F9:F13) -> 75271949 | G14: =SUM(G9:G13) -> 89619958 | H14: =SUM(H9:H13) -> 93598360 | I14: =SUM(I9:I13) -> 0
B16: Transfers
C17: Central Allocations | D17: =SUM('1003':'1856'!D28:D28) -> 102320067 | E17: =SUM('1003':'1856'!E28:E28) -> 109637763 | F17: =SUM('1003':'1856'!F28:F28) -> 109269980 | G17: =SUM('1003':'1856'!G28:G28) -> 114983732 | H17: =SUM('1003':'1856'!H28:H28) -> 110542968 | I17: =SUM('1003':'1856'!I28:I28) -> 0
C18: Central Allocations Out | D18: =SUM('1003':'1856'!D29:D29) -> -17149795 | E18: =SUM('1003':'1856'!E29:E29) -> -18149795 | F18: =SUM('1003':'1856'!F29:F29) -> -20517114 | G18: =SUM('1003':'1856'!G29:G29) -> -22073880 | H18: =SUM('1003':'1856'!H29:H29) -> -22073880 | I18: =SUM('1003':'1856'!I29:I29) -> 0
C19: Mandatory Transfers In | D19: =SUM('1003':'1856'!D30:D30) -> 0 | E19: =SUM('1003':'1856'!E30:E30) -> 0 | F19: =SUM('1003':'1856'!F30:F30) -> 0 | G19: =SUM('1003':'1856'!G30:G30) -> 0 | H19: =SUM('1003':'1856'!H30:H30) -> 0 | I19: =SUM('1003':'1856'!I30:I30) -> 0
C20: Mandatory Transfers Out | D20: =SUM('1003':'1856'!D31:D31) -> 0 | E20: =SUM('1003':'1856'!E31:E31) -> 0 | F20: =SUM('1003':'1856'!F31:F31) -> 0 | G20: =SUM('1003':'1856'!G31:G31) -> 0 | H20: =SUM('1003':'1856'!H31:H31) -> 0 | I20: =SUM('1003':'1856'!I31:I31) -> 0
C21: Non-Mandatory Transfers In | D21: =SUM('1003':'1856'!D32:D32) -> 60297336 | E21: =SUM('1003':'1856'!E32:E32) -> 66814903 | F21: =SUM('1003':'1856'!F32:F32) -> 1.1129171e+08 | G21: =SUM('1003':'1856'!G32:G32) -> 74080644 | H21: =SUM('1003':'1856'!H32:H32) -> 11335913 | I21: =SUM('1003':'1856'!I32:I32) -> 0
C22: Non-Mandatory Transfers Out | D22: =SUM('1003':'1856'!D33:D33) -> -64867730 | E22: =SUM('1003':'1856'!E33:E33) -> -77996639 | F22: =SUM('1003':'1856'!F33:F33) -> -1.3349167e+08 | G22: =SUM('1003':'1856'!G33:G33) -> -85529152 | H22: =SUM('1003':'1856'!H33:H33) -> -13589205 | I22: =SUM('1003':'1856'!I33:I33) -> 0
C23: NM Transfer Out for Equipment Reserve | D23: =SUM('1003':'1856'!D34:D34) -> 0 | E23: =SUM('1003':'1856'!E34:E34) -> 0 | F23: =SUM('1003':'1856'!F34:F34) -> 0 | G23: =SUM('1003':'1856'!G34:G34) -> 0 | H23: =SUM('1003':'1856'!H34:H34) -> 0 | I23: =SUM('1003':'1856'!I34:I34) -> 0
A24: c | C24: Net Transfers | D24: =SUM(D17:D23) -> 80599879 | E24: =SUM(E17:E23) -> 80306232 | F24: =SUM(F17:F23) -> 66552905 | G24: =SUM(G17:G23) -> 81461343 | H24: =SUM(H17:H23) -> 86215796 | I24: =SUM(I17:I23) -> 0
A26: d | B26: TOTAL NET RESOURCES (a+b+c) | D26: =+D24+D14+D6 -> 1.667079e+08 | E26: =+E24+E14+E6 -> 1.7822796e+08 | F26: =+F24+F14+F6 -> 1.6763924e+08 | G26: =+G24+G14+G6 -> 1.8599548e+08 | H26: =+H24+H14+H6 -> 2.0031039e+08 | I26: =+I24+I14+I6 -> 23394375
A28: EXPENDITURES
B29: Expenditures by Function Type
C30: Instruction | D30: =SUM('1003':'1856'!D41:D41) -> 0 | E30: =SUM('1003':'1856'!E41:E41) -> 0 | F30: =SUM('1003':'1856'!F41:F41) -> 0 | G30: =SUM('1003':'1856'!G41:G41) -> 0 | H30: =SUM('1003':'1856'!H41:H41) -> 0 | I30: =SUM('1003':'1856'!I41:I41) -> 0
C31: Research | D31: =SUM('1003':'1856'!D42:D42) -> 0 | E31: =SUM('1003':'1856'!E42:E42) -> 0 | F31: =SUM('1003':'1856'!F42:F42) -> 0 | G31: =SUM('1003':'1856'!G42:G42) -> 0 | H31: =SUM('1003':'1856'!H42:H42) -> 0 | I31: =SUM('1003':'1856'!I42:I42) -> 0
C32: Public Service | D32: =SUM('1003':'1856'!D43:D43) -> 0 | E32: =SUM('1003':'1856'!E43:E43) -> 0 | F32: =SUM('1003':'1856'!F43:F43) -> 24.38 | G32: =SUM('1003':'1856'!G43:G43) -> 7062.79 | H32: =SUM('1003':'1856'!H43:H43) -> 0 | I32: =SUM('1003':'1856'!I43:I43) -> 0
C33: Academic Support | D33: =SUM('1003':'1856'!D44:D44) -> 80 | E33: =SUM('1003':'1856'!E44:E44) -> 88 | F33: =SUM('1003':'1856'!F44:F44) -> 3653.7 | G33: =SUM('1003':'1856'!G44:G44) -> 0 | H33: =SUM('1003':'1856'!H44:H44) -> 0 | I33: =SUM('1003':'1856'!I44:I44) -> 0
C34: Student Services | D34: =SUM('1003':'1856'!D45:D45) -> 0 | E34: =SUM('1003':'1856'!E45:E45) -> 0 | F34: =SUM('1003':'1856'!F45:F45) -> 0 | G34: =SUM('1003':'1856'!G45:G45) -> 0 | H34: =SUM('1003':'1856'!H45:H45) -> 0 | I34: =SUM('1003':'1856'!I45:I45) -> 0
C35: Institutional Support | D35: =SUM('1003':'1856'!D46:D46) -> 385681.67 | E35: =SUM('1003':'1856'!E46:E46) -> 375804.41 | F35: =SUM('1003':'1856'!F46:F46) -> 398583.8 | G35: =SUM('1003':'1856'!G46:G46) -> 373227.04 | H35: =SUM('1003':'1856'!H46:H46) -> 0 | I35: =SUM('1003':'1856'!I46:I46) -> 0
C36: Operation & Maint. of Plant | D36: =SUM('1003':'1856'!D47:D47) -> 1.3717476e+08 | E36: =SUM('1003':'1856'!E47:E47) -> 1.5203769e+08 | F36: =SUM('1003':'1856'!F47:F47) -> 1.523228e+08 | G36: =SUM('1003':'1856'!G47:G47) -> 1.6511895e+08 | H36: =SUM('1003':'1856'!H47:H47) -> 176916016 | I36: =SUM('1003':'1856'!I47:I47) -> 0
C37: Scholarships & Fellowships | D37: =SUM('1003':'1856'!D48:D48) -> 0 | E37: =SUM('1003':'1856'!E48:E48) -> 0 | F37: =SUM('1003':'1856'!F48:F48) -> 0 | G37: =SUM('1003':'1856'!G48:G48) -> 0 | H37: =SUM('1003':'1856'!H48:H48) -> 0 | I37: =SUM('1003':'1856'!I48:I48) -> 0
C38: Auxiliary Enterprises | D38: =SUM('1003':'1856'!D49:D49) -> 0 | E38: =SUM('1003':'1856'!E49:E49) -> 0 | F38: =SUM('1003':'1856'!F49:F49) -> 0 | G38: =SUM('1003':'1856'!G49:G49) -> 0 | H38: =SUM('1003':'1856'!H49:H49) -> 0 | I38: =SUM('1003':'1856'!I49:I49) -> 0
C39: Hospital | D39: =SUM('1003':'1856'!D50:D50) -> 0 | E39: =SUM('1003':'1856'!E50:E50) -> 0 | F39: =SUM('1003':'1856'!F50:F50) -> 0 | G39: =SUM('1003':'1856'!G50:G50) -> 0 | H39: =SUM('1003':'1856'!H50:H50) -> 0 | I39: =SUM('1003':'1856'!I50:I50) -> 0
C40: Income Accounts | D40: =SUM('1003':'1856'!D51:D51) -> 0 | E40: =SUM('1003':'1856'!E51:E51) -> 0 | F40: =SUM('1003':'1856'!F51:F51) -> 0 | G40: =SUM('1003':'1856'!G51:G51) -> 0 | H40: =SUM('1003':'1856'!H51:H51) -> 0 | I40: =SUM('1003':'1856'!I51:I51) -> 0
C41: Independant Operations | D41: =SUM('1003':'1856'!D52:D52) -> 0 | E41: =SUM('1003':'1856'!E52:E52) -> 0 | F41: =SUM('1003':'1856'!F52:F52) -> 0 | G41: =SUM('1003':'1856'!G52:G52) -> 0 | H41: =SUM('1003':'1856'!H52:H52) -> 0 | I41: =SUM('1003':'1856'!I52:I52) -> 0
C42: TOTAL EXPENDITURES | D42: =SUM(D30:D41) -> 1.3756052e+08 | E42: =SUM(E30:E41) -> 1.5241358e+08 | F42: =SUM(F30:F41) -> 1.5272506e+08 | G42: =SUM(G30:G41) -> 1.6549924e+08 | H42: =SUM(H30:H41) -> 176916016 | I42: =SUM(I30:I41) -> 0
B44: Expenditures by Object Class
C45: Salaries | D45: =SUM('1003':'1856'!D56:D56) -> 40052397 | E45: =SUM('1003':'1856'!E56:E56) -> 46136456 | F45: =SUM('1003':'1856'!F56:F56) -> 46618817 | G45: =SUM('1003':'1856'!G56:G56) -> 48468374 | H45: =SUM('1003':'1856'!H56:H56) -> 40736207 | I45: =SUM('1003':'1856'!I56:I56) -> 0
C46: Fringe Benefits | D46: =SUM('1003':'1856'!D57:D57) -> 13603740 | E46: =SUM('1003':'1856'!E57:E57) -> 16505864 | F46: =SUM('1003':'1856'!F57:F57) -> 17529566 | G46: =SUM('1003':'1856'!G57:G57) -> 18602670 | H46: =SUM('1003':'1856'!H57:H57) -> 15203919 | I46: =SUM('1003':'1856'!I57:I57) -> 0
...

Sheet 1003
A1: TFAC -- Fund:1003 | F1: Fiscal Pages
C3: Current Non Sponsored Fund | D3: Actual | E3: Actual | F3: Actual | G3: Period 14 | H3: Projected | I3: Budget
C4: Excluding Multi Year accounts | D4: 1999-2000 | E4: 2000-01 | F4: 2001-02 | G4: 2002-03 | H4: 2003-04 | I4: 2004-05
A5: RESOURCES
A6: a | B6: Carry Forward | D6: =+E6+D72-D25-D35 -> 9183762.4 | E6: =+F6+E72-E25-E35 -> 18387551 | F6: =+G6+F72-F25-F35 -> 26982018 | G6: 21451646 | H6: =G6+G25+G35-G53 -> 19543849 | I6: =H6+H25+H35-H53 -> 19543849
B8: Revenues by Revenue Class
C9: Tuition | D9: 0 | E9: 0 | F9: 0 | G9: 0 | H9: 0 | I9: 0
C10: Appropriations (other than O & M) | D10: 0 | E10: 0 | F10: 0 | G10: 0 | H10: 0 | I10: 0
C11: Grants & Contracts | D11: 0 | E11: 0 | F11: 0 | G11: 0 | H11: 0 | I11: 0
C12: Student Course & Lab Fees | D12: 0 | E12: 0 | F12: 0 | G12: 0 | H12: 0 | I12: 0
C13: Indirect Cost Recovery | D13: 0 | E13: 0 | F13: 0 | G13: 0 | H13: 0 | I13: 0
C14: External & Educational Sales | D14: 23225.6 | E14: 47132.09 | F14: 26257.77 | G14: 46194.68 | H14: 22000 | I14: 0
C15: Internal Sales | D15: 0.35 | E15: 31319 | F15: 18196.43 | G15: -1278 | H15: 0 | I15: 0
C16: Gifts & Bequests | D16: 50 | E16: 0 | F16: 0 | G16: 0 | H16: 0 | I16: 0
C17: Endowment Income | D17: 0 | E17: 0 | F17: 0 | G17: 0 | H17: 0 | I17: 0
C18: Investment Income | D18: 31358.14 | E18: 0 | F18: 0 | G18: 0 | H18: 0 | I18: 0
C19: Hospital & Hosp. Clinic Sales & Services | D19: 0 | E19: 0 | F19: 0 | G19: 0 | H19: 0 | I19: 0
C20: Private Practice | D20: 0 | E20: 0 | F20: 0 | G20: 0 | H20: 0 | I20: 0
... C24: Other Revenues | D24: 0 | E24: 0 | F24: 0 | G24: 0 | H24: 0 | I24: 0
A25: b | C25: Total Revenues | D25: =SUM(D9:D24) -> 54634.09 | E25: =SUM(E9:E24) -> 78451.09 | F25: =SUM(F9:F24) -> 44454.2 | G25: =SUM(G9:G24) -> 44916.68 | H25: =SUM(H9:H24) -> 22000 | I25: =SUM(I9:I24) -> 0
B27: Transfers
C28: Central Allocations | D28: 85170272 | E28: 91487968 | F28: 88752866 | G28: 92909852 | H28: 88469088 | I28: 0
C29: Central Allocations Out | D29: 0 | E29: 0 | F29: 0 | G29: 0 | H29: 0 | I29: 0
C30: Mandatory Transfers In | D30: 0 | E30: 0 | F30: 0 | G30: 0 | H30: 0 | I30: 0
C31: Mandatory Transfers Out | D31: 0 | E31: 0 | F31: 0 | G31: 0 | H31: 0 | I31: 0
C32: Non-Mandatory Transfers In | D32: 23128004 | E32: 17167204 | F32: 17070037 | G32: 23721570 | H32: 11335913 | I32: 0
C33: Non-Mandatory Transfers Out | D33: -24127835 | E33: -24262759 | F33: -30206308 | G33: -27822037 | H33: -3542301 | I33: 0
C34: NM Transfer Out for Equipment Reserve | D34: 0 | E34: 0 | F34: 0 | G34: 0 | H34: 0 | I34: 0
A35: c | C35: Net Transfers | D35: =SUM(D28:D34) -> 84170441 | E35: =SUM(E28:E34) -> 84392413 | F35: =SUM(F28:F34) -> 75616595 | G35: =SUM(G28:G34) -> 88809384 | H35: =SUM(H28:H34) -> 96262700 | I35: =SUM(I28:I34) -> 0
A37: d | B37: TOTAL NET RESOURCES (a+b+c) | D37: =+D35+D25+D6 -> 93408838 | E37: =+E35+E25+E6 -> 1.0285842e+08 | F37: =+F35+F25+F6 -> 1.0264307e+08 | G37: =+G35+G25+G6 -> 1.1030595e+08 | H37: =+H35+H25+H6 -> 1.1582855e+08 | I37: =+I35+I25+I6 -> 19543849
A39: EXPENDITURES
B40: Expenditures by Function Type
C41: Instruction | D41: 0 | E41: 0 | F41: 0 | G41: 0 | H41: 0 | I41: 0
C42: Research | D42: 0 | E42: 0 | F42: 0 | G42: 0 | H42: 0 | I42: 0
C43: Public Service | D43: 0 | E43: 0 | F43: 0 | G43: 0 | H43: 0 | I43: 0
C44: Academic Support | D44: 0 | E44: 0 | F44: 0 | G44: 0 | H44: 0 | I44: 0
C45: Student Services | D45: 0 | E45: 0 | F45: 0 | G45: 0 | H45: 0 | I45: 0
C46: Institutional Support | D46: 385681.67 | E46: 375804.41 | F46: 398583.8 | G46: 373227.04 | H46: 0 | I46: 0
C47: Operation & Maint. of Plant | D47: 74635605 | E47: 75500593 | F47: 80792837 | G47: 90388871 | H47: 96284700 | I47: 0
C48: Scholarships & Fellowships | D48: 0 | E48: 0 | F48: 0 | G48: 0 | H48: 0 | I48: 0
...

Sheet 1043
A1: TFAC -- Fund:1043 | F1: Fiscal Pages
C3: Current Non Sponsored Fund | D3: Actual | E3: Actual | F3: Actual | G3: Period 14 | H3: Projected | I3: Budget
C4: Excluding Multi Year accounts | D4: 1999-2000 | E4: 2000-01 | F4: 2001-02 | G4: 2002-03 | H4: 2003-04 | I4: 2004-05
A5: RESOURCES
A6: a | B6: Carry Forward | D6: =+E6+D72-D25-D35 -> 22 | E6: =+F6+E72-E25-E35 -> 2 | F6: =+G6+F72-F25-F35 -> 2.03 | G6: 2.03 | H6: =G6+G25+G35-G53 -> 2.03 | I6: =H6+H25+H35-H53 -> 2.03
B8: Revenues by Revenue Class
C9: Tuition | D9: 0 | E9: 0 | F9: 0 | G9: 0 | H9: 0 | I9: 0
C10: Appropriations (other than O & M) | D10: 0 | E10: 0 | F10: 0 | G10: 0 | H10: 0 | I10: 0
C11: Grants & Contracts | D11: 0 | E11: 0 | F11: 0 | G11: 0 | H11: 0 | I11: 0
C12: Student Course & Lab Fees | D12: 0 | E12: 0 | F12: 0 | G12: 0 | H12: 0 | I12: 0
C13: Indirect Cost Recovery | D13: 17149795 | E13: 18149795 | F13: 20517114 | G13: 22073880 | H13: 22073880 | I13: 0
C14: External & Educational Sales | D14: 0 | E14: 0 | F14: 0 | G14: 0 | H14: 0 | I14: 0
C15: Internal Sales | D15: 0 | E15: 0 | F15: 0 | G15: 0 | H15: 0 | I15: 0
C16: Gifts & Bequests | D16: 0 | E16: 0 | F16: 0 | G16: 0 | H16: 0 | I16: 0
C17: Endowment Income | D17: 0 | E17: 0 | F17: 0 | G17: 0 | H17: 0 | I17: 0
C18: Investment Income | D18: 0 | E18: 0 | F18: 0 | G18: 0 | H18: 0 | I18: 0
C19: Hospital & Hosp. Clinic Sales & Services | D19: 0 | E19: 0 | F19: 0 | G19: 0 | H19: 0 | I19: 0
C20: Private Practice | D20: 0 | E20: 0 | F20: 0 | G20: 0 | H20: 0 | I20: 0
... C24: Other Revenues | D24: 0 | E24: 0 | F24: 0 | G24: 0 | H24: 0 | I24: 0
A25: b | C25: Total Revenues | D25: =SUM(D9:D24) -> 17149795 | E25: =SUM(E9:E24) -> 18149795 | F25: =SUM(F9:F24) -> 20517114 | G25: =SUM(G9:G24) -> 22073880 | H25: =SUM(H9:H24) -> 22073880 | I25: =SUM(I9:I24) -> 0
B27: Transfers
C28: Central Allocations | D28: 17149795 | E28: 18149795 | F28: 20517114 | G28: 22073880 | H28: 22073880 | I28: 0
C29: Central Allocations Out | D29: -17149795 | E29: -18149795 | F29: -20517114 | G29: -22073880 | H29: -22073880 | I29: 0
C30: Mandatory Transfers In | D30: 0 | E30: 0 | F30: 0 | G30: 0 | H30: 0 | I30: 0
C31: Mandatory Transfers Out | D31: 0 | E31: 0 | F31: 0 | G31: 0 | H31: 0 | I31: 0
C32: Non-Mandatory Transfers In | D32: 0 | E32: 0 | F32: 0 | G32: 0 | H32: 0 | I32: 0
C33: Non-Mandatory Transfers Out | D33: 0 | E33: 0 | F33: 0 | G33: 0 | H33: 0 | I33: 0
C34: NM Transfer Out for Equipment Reserve | D34: 0 | E34: 0 | F34: 0 | G34: 0 | H34: 0 | I34: 0
A35: c | C35: Net Transfers | D35: =SUM(D28:D34) -> 0 | E35: =SUM(E28:E34) -> 0 | F35: =SUM(F28:F34) -> 0 | G35: =SUM(G28:G34) -> 0 | H35: =SUM(H28:H34) -> 0 | I35: =SUM(I28:I34) -> 0
A37: d | B37: TOTAL NET RESOURCES (a+b+c) | D37: =+D35+D25+D6 -> 17149817 | E37: =+E35+E25+E6 -> 18149797 | F37: =+F35+F25+F6 -> 20517116 | G37: =+G35+G25+G6 -> 22073882 | H37: =+H35+H25+H6 -> 22073882 | I37: =+I35+I25+I6 -> 2.03
A39: EXPENDITURES
B40: Expenditures by Function Type
C41: Instruction | D41: 0 | E41: 0 | F41: 0 | G41: 0 | H41: 0 | I41: 0
C42: Research | D42: 0 | E42: 0 | F42: 0 | G42: 0 | H42: 0 | I42: 0
C43: Public Service | D43: 0 | E43: 0 | F43: 0 | G43: 0 | H43: 0 | I43: 0
C44: Academic Support | D44: 0 | E44: 0 | F44: 0 | G44: 0 | H44: 0 | I44: 0
C45: Student Services | D45: 0 | E45: 0 | F45: 0 | G45: 0 | H45: 0 | I45: 0
C46: Institutional Support | D46: 0 | E46: 0 | F46: 0 | G46: 0 | H46: 0 | I46: 0
C47: Operation & Maint. of Plant | D47: 17149815 | E47: 18149795 | F47: 20517114 | G47: 22073880 | H47: 22073880 | I47: 0
C48: Scholarships & Fellowships | D48: 0 | E48: 0 | F48: 0 | G48: 0 | H48: 0 | I48: 0
...

Sheet 1166
A1: TFAC -- Fund:1166 | F1: Fiscal Pages
C3: Current Non Sponsored Fund | D3: Actual | E3: Actual | F3: Actual | G3: Period 14 | H3: Projected | I3: Budget
C4: Excluding Multi Year accounts | D4: 1999-2000 | E4: 2000-01 | F4: 2001-02 | G4: 2002-03 | H4: 2003-04 | I4: 2004-05
A5: RESOURCES
A6: a | B6: Carry Forward | D6: =+E6+D72-D25-D35 -> 12324596 | E6: =+F6+E72-E25-E35 -> 9337658 | F6: =+G6+F72-F25-F35 -> -4982196.5 | G6: -7775381.7 | H6: =G6+G25+G35-G53 -> -1463386.1 | I6: =H6+H25+H35-H53 -> 1434737.9
B8: Revenues by Revenue Class
C9: Tuition | D9: 0 | E9: 0 | F9: 0 | G9: 0 | H9: 0 | I9: 0
C10: Appropriations (other than O & M) | D10: 0 | E10: 0 | F10: 0 | G10: 0 | H10: 0 | I10: 0
C11: Grants & Contracts | D11: 0 | E11: 0 | F11: 0 | G11: 0 | H11: 0 | I11: 0
C12: Student Course & Lab Fees | D12: 0 | E12: 0 | F12: 0 | G12: 0 | H12: 0 | I12: 0
C13: Indirect Cost Recovery | D13: 0 | E13: 0 | F13: 0 | G13: 0 | H13: 0 | I13: 0
C14: External & Educational Sales | D14: 1407057.1 | E14: 1119796.4 | F14: 1596873.3 | G14: 1851644.1 | H14: 4713397 | I14: 0
C15: Internal Sales | D15: 43821749 | E15: 47007484 | F15: 50410932 | G15: 62729574 | H15: 66789067 | I15: 0
C16: Gifts & Bequests | D16: 0 | E16: 0 | F16: 0 | G16: 0 | H16: 0 | I16: 0
C17: Endowment Income | D17: 0 | E17: 0 | F17: 0 | G17: 0 | H17: 0 | I17: 0
C18: Investment Income | D18: 0 | E18: 0 | F18: 0 | G18: 0 | H18: 0 | I18: 0
C19: Hospital & Hosp. Clinic Sales & Services | D19: 0 | E19: 0 | F19: 0 | G19: 0 | H19: 0 | I19: 0
C20: Private Practice | D20: 0 | E20: 0 | F20: 0 | G20: 0 | H20: 0 | I20: 0
... C24: Other Revenues | D24: 0 | E24: 0 | F24: 0 | G24: 0 | H24: 0 | I24: 0
A25: b | C25: Total Revenues | D25: =SUM(D9:D24) -> 45228806 | E25: =SUM(E9:E24) -> 48127280 | F25: =SUM(F9:F24) -> 52007806 | G25: =SUM(G9:G24) -> 64581218 | H25: =SUM(H9:H24) -> 71502464 | I25: =SUM(I9:I24) -> 0
B27: Transfers
C28: Central Allocations | D28: 0 | E28: 0 | F28: 0 | G28: 0 | H28: 0 | I28: 0
C29: Central Allocations Out | D29: 0 | E29: 0 | F29: 0 | G29: 0 | H29: 0 | I29: 0
C30: Mandatory Transfers In | D30: 0 | E30: 0 | F30: 0 | G30: 0 | H30: 0 | I30: 0
C31: Mandatory Transfers Out | D31: 0 | E31: 0 | F31: 0 | G31: 0 | H31: 0 | I31: 0
C32: Non-Mandatory Transfers In | D32: 31002514 | E32: 31352160 | F32: 76645990 | G32: 38051435 | H32: 0 | I32: 0
C33: Non-Mandatory Transfers Out | D33: -40739894 | E33: -42539452 | F33: -87885516 | G33: -51027475 | H33: -10046904 | I33: 0
C34: NM Transfer Out for Equipment Reserve | D34: 0 | E34: 0 | F34: 0 | G34: 0 | H34: 0 | I34: 0
A35: c | C35: Net Transfers | D35: =SUM(D28:D34) -> -9737380.4 | E35: =SUM(E28:E34) -> -11187292 | F35: =SUM(F28:F34) -> -11239526 | G35: =SUM(G28:G34) -> -12976040 | H35: =SUM(H28:H34) -> -10046904 | I35: =SUM(I28:I34) -> 0
A37: d | B37: TOTAL NET RESOURCES (a+b+c) | D37: =+D35+D25+D6 -> 47816022 | E37: =+E35+E25+E6 -> 46277647 | F37: =+F35+F25+F6 -> 35786083 | G37: =+G35+G25+G6 -> 43829796 | H37: =+H35+H25+H6 -> 59992174 | I37: =+I35+I25+I6 -> 1434737.9
A39: EXPENDITURES
B40: Expenditures by Function Type
C41: Instruction | D41: 0 | E41: 0 | F41: 0 | G41: 0 | H41: 0 | I41: 0
C42: Research | D42: 0 | E42: 0 | F42: 0 | G42: 0 | H42: 0 | I42: 0
C43: Public Service | D43: 0 | E43: 0 | F43: 0 | G43: 0 | H43: 0 | I43: 0
C44: Academic Support | D44: 0 | E44: 0 | F44: 0 | G44: 0 | H44: 0 | I44: 0
C45: Student Services | D45: 0 | E45: 0 | F45: 0 | G45: 0 | H45: 0 | I45: 0
C46: Institutional Support | D46: 0 | E46: 0 | F46: 0 | G46: 0 | H46: 0 | I46: 0
C47: Operation & Maint. of Plant | D47: 38478364 | E47: 51259843 | F47: 43561465 | G47: 45293182 | H47: 58557436 | I47: 0
C48: Scholarships & Fellowships | D48: 0 | E48: 0 | F48: 0 | G48: 0 | H48: 0 | I48: 0
...

Sheet 1198
A1: TFAC -- Fund:1198 | F1: Fiscal Pages
C3: Current Non Sponsored Fund | D3: Actual | E3: Actual | F3: Actual | G3: Period 14 | H3: Projected | I3: Budget
C4: Excluding Multi Year accounts | D4: 1999-2000 | E4: 2000-01 | F4: 2001-02 | G4: 2002-03 | H4: 2003-04 | I4: 2004-05
A5: RESOURCES
A6: a | B6: Carry Forward | D6: =+E6+D72-D25-D35 -> -139054.93 | E6: =+F6+E72-E25-E35 -> 1372277.6 | F6: =+G6+F72-F25-F35 -> 3793211.9 | G6: 1216708.7 | H6: =G6+G25+G35-G53 -> 2389260.1 | I6: =H6+H25+H35-H53 -> 2389260.1
B8: Revenues by Revenue Class
C9: Tuition | D9: 0 | E9: 0 | F9: 0 | G9: 0 | H9: 0 | I9: 0
C10: Appropriations (other than O & M) | D10: 0 | E10: 0 | F10: 0 | G10: 0 | H10: 0 | I10: 0
C11: Grants & Contracts | D11: 0 | E11: 0 | F11: 0 | G11: 0 | H11: 0 | I11: 0
C12: Student Course & Lab Fees | D12: 0 | E12: 0 | F12: 0 | G12: 0 | H12: 0 | I12: 0
C13: Indirect Cost Recovery | D13: 0 | E13: 0 | F13: 0 | G13: 0 | H13: 0 | I13: 0
C14: External & Educational Sales | D14: 2296535.6 | E14: 2413816.7 | F14: 2700375 | G14: 2906794 | H14: 0 | I14: 0
C15: Internal Sales | D15: -974.6 | E15: 0 | F15: 0 | G15: 0 | H15: 0 | I15: 0
C16: Gifts & Bequests | D16: 0 | E16: 0 | F16: 0 | G16: 0 | H16: 0 | I16: 0
C17: Endowment Income | D17: 0 | E17: 0 | F17: 0 | G17: 0 | H17: 0 | I17: 0
C18: Investment Income | D18: 0 | E18: 0 | F18: 0 | G18: 0 | H18: 0 | I18: 0
C19: Hospital & Hosp. Clinic Sales & Services | D19: 0 | E19: 0 | F19: 0 | G19: 0 | H19: 0 | I19: 0
C20: Private Practice | D20: 0 | E20: 0 | F20: 0 | G20: 0 | H20: 0 | I20: 0
... C24: Other Revenues | D24: 0 | E24: 0 | F24: 0 | G24: 0 | H24: 0 | I24: 0
A25: b | C25: Total Revenues | D25: =SUM(D9:D24) -> 2295561 | E25: =SUM(E9:E24) -> 2413816.7 | F25: =SUM(F9:F24) -> 2700375 | G25: =SUM(G9:G24) -> 2906794 | H25: =SUM(H9:H24) -> 0 | I25: =SUM(I9:I24) -> 0
B27: Transfers
C28: Central Allocations | D28: 0 | E28: 0 | F28: 0 | G28: 0 | H28: 0 | I28: 0
C29: Central Allocations Out | D29: 0 | E29: 0 | F29: 0 | G29: 0 | H29: 0 | I29: 0
C30: Mandatory Transfers In | D30: 0 | E30: 0 | F30: 0 | G30: 0 | H30: 0 | I30: 0
C31: Mandatory Transfers Out | D31: 0 | E31: 0 | F31: 0 | G31: 0 | H31: 0 | I31: 0
C32: Non-Mandatory Transfers In | D32: 6126750 | E32: 18295539 | F32: 17565678 | G32: 12307639 | H32: 0 | I32: 0
C33: Non-Mandatory Transfers Out | D33: 0 | E33: -11160965 | F33: -15399842 | G33: -6679640.3 | H33: 0 | I33: 0
C34: NM Transfer Out for Equipment Reserve | D34: 0 | E34: 0 | F34: 0 | G34: 0 | H34: 0 | I34: 0
A35: c | C35: Net Transfers | D35: =SUM(D28:D34) -> 6126750 | E35: =SUM(E28:E34) -> 7134573.7 | F35: =SUM(F28:F34) -> 2165836.2 | G35: =SUM(G28:G34) -> 5627998.5 | H35: =SUM(H28:H34) -> 0 | I35: =SUM(I28:I34) -> 0
A37: d | B37: TOTAL NET RESOURCES (a+b+c) | D37: =+D35+D25+D6 -> 8283256.1 | E37: =+E35+E25+E6 -> 10920668 | F37: =+F35+F25+F6 -> 8659423.1 | G37: =+G35+G25+G6 -> 9751501.3 | H37: =+H35+H25+H6 -> 2389260.1 | I37: =+I35+I25+I6 -> 2389260.1
A39: EXPENDITURES
B40: Expenditures by Function Type
C41: Instruction | D41: 0 | E41: 0 | F41: 0 | G41: 0 | H41: 0 | I41: 0
C42: Research | D42: 0 | E42: 0 | F42: 0 | G42: 0 | H42: 0 | I42: 0
C43: Public Service | D43: 0 | E43: 0 | F43: 24.38 | G43: 7062.79 | H43: 0 | I43: 0
C44: Academic Support | D44: 0 | E44: 0 | F44: 0 | G44: 0 | H44: 0 | I44: 0
C45: Student Services | D45: 0 | E45: 0 | F45: 0 | G45: 0 | H45: 0 | I45: 0
C46: Institutional Support | D46: 0 | E46: 0 | F46: 0 | G46: 0 | H46: 0 | I46: 0
C47: Operation & Maint. of Plant | D47: 6910978.5 | E47: 7127456 | F47: 7442690 | G47: 7355178.4 | H47: 0 | I47: 0
C48: Scholarships & Fellowships | D48: 0 | E48: 0 | F48: 0 | G48: 0 | H48: 0 | I48: 0
...

Sheet 1856
A1: TFAC -- Fund:1856 | F1: Fiscal Pages
C3: Current Non Sponsored Fund | D3: Actual | E3: Actual | F3: Actual | G3: Period 14 | H3: Projected | I3: Budget
C4: Excluding Multi Year accounts | D4: 1999-2000 | E4: 2000-01 | F4: 2001-02 | G4: 2002-03 | H4: 2003-04 | I4: 2004-05
A5: RESOURCES
A6: a | B6: Carry Forward | D6: =+E6+D72-D25-D35 -> 4356.03 | E6: =+F6+E72-E25-E35 -> 49886.9 | F6: =+G6+F72-F25-F35 -> 21349.63 | G6: 21200 | H6: =G6+G25+G35-G53 -> 26509.68 | I6: =H6+H25+H35-H53 -> 26525.68
B8: Revenues by Revenue Class
C9: Tuition | D9: 0 | E9: 0 | F9: 0 | G9: 0 | H9: 0 | I9: 0
C10: Appropriations (other than O & M) | D10: 0 | E10: 0 | F10: 0 | G10: 0 | H10: 0 | I10: 0
C11: Grants & Contracts | D11: 0 | E11: 0 | F11: 0 | G11: 0 | H11: 0 | I11: 0
C12: Student Course & Lab Fees | D12: 0 | E12: 0 | F12: 0 | G12: 0 | H12: 0 | I12: 0
C13: Indirect Cost Recovery | D13: 0 | E13: 0 | F13: 0 | G13: 0 | H13: 0 | I13: 0
C14: External & Educational Sales | D14: 0 | E14: 300 | F14: 0 | G14: 0 | H14: 0 | I14: 0
C15: Internal Sales | D15: 0 | E15: 0 | F15: 0 | G15: 0 | H15: 0 | I15: 0
C16: Gifts & Bequests | D16: 5000 | E16: 4000 | F16: 2200 | G16: 13150 | H16: 0 | I16: 0
C17: Endowment Income | D17: 0 | E17: 0 | F17: 0 | G17: 0 | H17: 0 | I17: 0
C18: Investment Income | D18: 543.16 | E18: 713.73 | F18: 0 | G18: 0 | H18: 0 | I18: 0
C19: Hospital & Hosp. Clinic Sales & Services | D19: 0 | E19: 0 | F19: 0 | G19: 0 | H19: 0 | I19: 0
C20: Private Practice | D20: 0 | E20: 0 | F20: 0 | G20: 0 | H20: 0 | I20: 0
... C24: Other Revenues | D24: 0 | E24: 0 | F24: 0 | G24: 0 | H24: 0 | I24: 0
A25: b | C25: Total Revenues | D25: =SUM(D9:D24) -> 5543.16 | E25: =SUM(E9:E24) -> 5013.73 | F25: =SUM(F9:F24) -> 2200 | G25: =SUM(G9:G24) -> 13150 | H25: =COUNT(H9:H24) -> 16 | I25: =SUM(I9:I24) -> 0
B27: Transfers
C28: Central Allocations | D28: 0 | E28: 0 | F28: 0 | G28: 0 | H28: 0 | I28: 0
C29: Central Allocations Out | D29: 0 | E29: 0 | F29: 0 | G29: 0 | H29: 0 | I29: 0
C30: Mandatory Transfers In | D30: 0 | E30: 0 | F30: 0 | G30: 0 | H30: 0 | I30: 0
C31: Mandatory Transfers Out | D31: 0 | E31: 0 | F31: 0 | G31: 0 | H31: 0 | I31: 0
C32: Non-Mandatory Transfers In | D32: 40067.71 | E32: 0 | F32: 10000 | G32: 0 | H32: 0 | I32: 0
C33: Non-Mandatory Transfers Out | D33: 0 | E33: -33463 | F33: 0 | G33: 0 | H33: 0 | I33: 0
C34: NM Transfer Out for Equipment Reserve | D34: 0 | E34: 0 | F34: 0 | G34: 0 | H34: 0 | I34: 0
A35: c | C35: Net Transfers | D35: =SUM(D28:D34) -> 40067.71 | E35: =SUM(E28:E34) -> -33463 | F35: =SUM(F28:F34) -> 10000 | G35: =SUM(G28:G34) -> 0 | H35: =SUM(H28:H34) -> 0 | I35: =SUM(I28:I34) -> 0
A37: d | B37: TOTAL NET RESOURCES (a+b+c) | D37: =+D35+D25+D6 -> 49966.9 | E37: =+E35+E25+E6 -> 21437.63 | F37: =+F35+F25+F6 -> 33549.63 | G37: =+G35+G25+G6 -> 34350 | H37: =+H35+H25+H6 -> 26525.68 | I37: =+I35+I25+I6 -> 26525.68
A39: EXPENDITURES
B40: Expenditures by Function Type
C41: Instruction | D41: 0 | E41: 0 | F41: 0 | G41: 0 | H41: 0 | I41: 0
C42: Research | D42: 0 | E42: 0 | F42: 0 | G42: 0 | H42: 0 | I42: 0
C43: Public Service | D43: 0 | E43: 0 | F43: 0 | G43: 0 | H43: 0 | I43: 0
C44: Academic Support | D44: 80 | E44: 88 | F44: 3653.7 | G44: 0 | H44: 0 | I44: 0
C45: Student Services | D45: 0 | E45: 0 | F45: 0 | G45: 0 | H45: 0 | I45: 0
C46: Institutional Support | D46: 0 | E46: 0 | F46: 0 | G46: 0 | H46: 0 | I46: 0
C47: Operation & Maint. of Plant | D47: 0 | E47: 0 | F47: 8695.93 | G47: 7840.32 | H47: 0 | I47: 0
C48: Scholarships & Fellowships | D48: 0 | E48: 0 | F48: 0 | G48: 0 | H48: 0 | I48: 0
...
