Workbook

Sheet Instructions

Sheet Cash Flows
C2: Telecentre Name
C3: Cash Flow Model
C4: Years 1-3
I5: Year 1 | U5: Year 2 | AK5: Year 3
D6: Month 1 | E6: Month 2 | F6: Month 3 | G6: Month 4 | H6: Month 5 | I6: Month 6 | J6: Month 7 | K6: Month 8 | L6: Month 9 | M6: Month 10 | N6: Month 11 | O6: Month 12 | P6: Yr 1 Total | R6: Month 13 | S6: Month 14 | T6: Month 15 | U6: Month 16 | V6: Month 17 | W6: Month 18 | X6: Month 19 | Y6: Month 20 | Z6: Month 21 | AA6: Month 22 | AB6: Month 23 | AC6: Month 24 | AD6: Yr 2 Total | AF6: Month 25 | AG6: Month 26 | AH6: Month 27 | AI6: Month 28 | AJ6: Month 29 | AK6: Month 30 | AL6: Month 31 | AM6: Month 32 | AN6: Month 33 | AO6: Month 34 | AP6: Month 35 | AQ6: Month 36 | AR6: Yr 3 Total
A7: Cash Inflows:
B8: Financing Cash Flows: | AR8: =SUM(AF8:AQ8) -> 0
C9: Equity Investment | P9: =SUM(D9:O9) -> 0 | AD9: =SUM(R9:AC9) -> 0 | AR9: =SUM(AF9:AQ9) -> 0
C10: Loan Advances | P10: =SUM(D10:O10) -> 0 | AD10: =SUM(R10:AC10) -> 0 | AR10: =SUM(AF10:AQ10) -> 0
C11: Startup Grants | P11: =SUM(D11:O11) -> 0 | AD11: =SUM(R11:AC11) -> 0 | AR11: =SUM(AF11:AQ11) -> 0
C12: Sustaining Grants | P12: =SUM(D12:O12) -> 0 | AD12: =SUM(R12:AC12) -> 0 | AR12: =SUM(AF12:AQ12) -> 0
C13: Sale of Assets | P13: =SUM(D13:O13) -> 0 | AD13: =SUM(R13:AC13) -> 0 | AR13: =SUM(AF13:AQ13) -> 0
P14: =SUM(D14:O14) -> 0 | AD14: =SUM(R14:AC14) -> 0 | AR14: =SUM(AF14:AQ14) -> 0
B15: Total Financing Cash Inflows | D15: =SUM(D9:D14) -> 0 | E15: =SUM(E9:E14) -> 0 | F15: =SUM(F9:F14) -> 0 | G15: =SUM(G9:G14) -> 0 | H15: =SUM(H9:H14) -> 0 | I15: =SUM(I9:I14) -> 0 | J15: =SUM(J9:J14) -> 0 | K15: =SUM(K9:K14) -> 0 | ... O15: =SUM(O9:O14) -> 0 | P15: =SUM(D15:O15) -> 0 | R15: =SUM(R9:R14) -> 0 | S15: =SUM(S9:S14) -> 0 | T15: =SUM(T9:T14) -> 0 | U15: =SUM(U9:U14) -> 0 | V15: =SUM(V9:V14) -> 0 | W15: =SUM(W9:W14) -> 0 | X15: =SUM(X9:X14) -> 0 | Y15: =SUM(Y9:Y14) -> 0 | ... AC15: =SUM(AC9:AC14) -> 0 | AD15: =SUM(R15:AC15) -> 0 | AF15: =SUM(AF9:AF14) -> 0 | AG15: =SUM(AG9:AG14) -> 0 | AH15: =SUM(AH9:AH14) -> 0 | AI15: =SUM(AI9:AI14) -> 0 | AJ15: =SUM(AJ9:AJ14) -> 0 | AK15: =SUM(AK9:AK14) -> 0 | AL15: =SUM(AL9:AL14) -> 0 | AM15: =SUM(AM9:AM14) -> 0 | ... AQ15: =SUM(AQ9:AQ14) -> 0 | AR15: =SUM(AF15:AQ15) -> 0
B17: Operating Cash Inflows:
C18: Membership fees | D18: 0 | E18: =D18 -> 0 | F18: =E18 -> 0 | G18: =F18 -> 0 | H18: =G18 -> 0 | I18: =H18 -> 0 | J18: =I18 -> 0 | K18: =J18 -> 0 | L18: =K18 -> 0 | ... O18: =N18 -> 0 | P18: =SUM(D18:O18) -> 0 | R18: =O18 -> 0 | S18: =R18 -> 0 | T18: =S18 -> 0 | U18: =T18 -> 0 | V18: =U18 -> 0 | W18: =V18 -> 0 | X18: =W18 -> 0 | Y18: =X18 -> 0 | Z18: =Y18 -> 0 | ... AC18: =AB18 -> 0 | AD18: =SUM(R18:AC18) -> 0 | AF18: =AC18 -> 0 | AG18: =AF18 -> 0 | AH18: =AG18 -> 0 | AI18: =AH18 -> 0 | AJ18: =AI18 -> 0 | AK18: =AJ18 -> 0 | AL18: =AK18 -> 0 | AM18: =AL18 -> 0 | AN18: =AM18 -> 0 | ... AQ18: =AP18 -> 0 | AR18: =SUM(AF18:AQ18) -> 0
C19: Internet subscriptions | D19: 0 | E19: =D19 -> 0 | F19: =E19 -> 0 | G19: =F19 -> 0 | H19: =G19 -> 0 | I19: =H19 -> 0 | J19: =I19 -> 0 | K19: =J19 -> 0 | L19: =K19 -> 0 | ... O19: =N19 -> 0 | P19: =SUM(D19:O19) -> 0 | R19: =O19 -> 0 | S19: =R19 -> 0 | T19: =S19 -> 0 | U19: =T19 -> 0 | V19: =U19 -> 0 | W19: =V19 -> 0 | X19: =W19 -> 0 | Y19: =X19 -> 0 | Z19: =Y19 -> 0 | ... AC19: =AB19 -> 0 | AD19: =SUM(R19:AC19) -> 0 | AF19: =AC19 -> 0 | AG19: =AF19 -> 0 | AH19: =AG19 -> 0 | AI19: =AH19 -> 0 | AJ19: =AI19 -> 0 | AK19: =AJ19 -> 0 | AL19: =AK19 -> 0 | AM19: =AL19 -> 0 | AN19: =AM19 -> 0 | ... AQ19: =AP19 -> 0 | AR19: =SUM(AF19:AQ19) -> 0
C20: Telephone use | D20: 0 | E20: =D20 -> 0 | F20: =E20 -> 0 | G20: =F20 -> 0 | H20: =G20 -> 0 | I20: =H20 -> 0 | J20: =I20 -> 0 | K20: =J20 -> 0 | L20: =K20 -> 0 | ... O20: =N20 -> 0 | P20: =SUM(D20:O20) -> 0 | R20: =O20 -> 0 | S20: =R20 -> 0 | T20: =S20 -> 0 | U20: =T20 -> 0 | V20: =U20 -> 0 | W20: =V20 -> 0 | X20: =W20 -> 0 | Y20: =X20 -> 0 | Z20: =Y20 -> 0 | ... AC20: =AB20 -> 0 | AD20: =SUM(R20:AC20) -> 0 | AF20: =AC20 -> 0 | AG20: =AF20 -> 0 | AH20: =AG20 -> 0 | AI20: =AH20 -> 0 | AJ20: =AI20 -> 0 | AK20: =AJ20 -> 0 | AL20: =AK20 -> 0 | AM20: =AL20 -> 0 | AN20: =AM20 -> 0 | ... AQ20: =AP20 -> 0 | AR20: =SUM(AF20:AQ20) -> 0
C21: Fax | D21: 0 | E21: =D21 -> 0 | F21: =E21 -> 0 | G21: =F21 -> 0 | H21: =G21 -> 0 | I21: =H21 -> 0 | J21: =I21 -> 0 | K21: =J21 -> 0 | L21: =K21 -> 0 | ... O21: =N21 -> 0 | P21: =SUM(D21:O21) -> 0 | R21: =O21 -> 0 | S21: =R21 -> 0 | T21: =S21 -> 0 | U21: =T21 -> 0 | V21: =U21 -> 0 | W21: =V21 -> 0 | X21: =W21 -> 0 | Y21: =X21 -> 0 | Z21: =Y21 -> 0 | ... AC21: =AB21 -> 0 | AD21: =SUM(R21:AC21) -> 0 | AF21: =AC21 -> 0 | AG21: =AF21 -> 0 | AH21: =AG21 -> 0 | AI21: =AH21 -> 0 | AJ21: =AI21 -> 0 | AK21: =AJ21 -> 0 | AL21: =AK21 -> 0 | AM21: =AL21 -> 0 | AN21: =AM21 -> 0 | ... AQ21: =AP21 -> 0 | AR21: =SUM(AF21:AQ21) -> 0
C22: Photocopying | D22: 0 | E22: =D22 -> 0 | F22: =E22 -> 0 | G22: =F22 -> 0 | H22: =G22 -> 0 | I22: =H22 -> 0 | J22: =I22 -> 0 | K22: =J22 -> 0 | L22: =K22 -> 0 | ... O22: =N22 -> 0 | P22: =SUM(D22:O22) -> 0 | R22: =O22 -> 0 | S22: =R22 -> 0 | T22: =S22 -> 0 | U22: =T22 -> 0 | V22: =U22 -> 0 | W22: =V22 -> 0 | X22: =W22 -> 0 | Y22: =X22 -> 0 | Z22: =Y22 -> 0 | ... AC22: =AB22 -> 0 | AD22: =SUM(R22:AC22) -> 0 | AF22: =AC22 -> 0 | AG22: =AF22 -> 0 | AH22: =AG22 -> 0 | AI22: =AH22 -> 0 | AJ22: =AI22 -> 0 | AK22: =AJ22 -> 0 | AL22: =AK22 -> 0 | AM22: =AL22 -> 0 | AN22: =AM22 -> 0 | ... AQ22: =AP22 -> 0 | AR22: =SUM(AF22:AQ22) -> 0
C23: Scanning | D23: 0 | E23: =D23 -> 0 | F23: =E23 -> 0 | G23: =F23 -> 0 | H23: =G23 -> 0 | I23: =H23 -> 0 | J23: =I23 -> 0 | K23: =J23 -> 0 | L23: =K23 -> 0 | ... O23: =N23 -> 0 | P23: =SUM(D23:O23) -> 0 | R23: =O23 -> 0 | S23: =R23 -> 0 | T23: =S23 -> 0 | U23: =T23 -> 0 | V23: =U23 -> 0 | W23: =V23 -> 0 | X23: =W23 -> 0 | Y23: =X23 -> 0 | Z23: =Y23 -> 0 | ... AC23: =AB23 -> 0 | AD23: =SUM(R23:AC23) -> 0 | AF23: =AC23 -> 0 | AG23: =AF23 -> 0 | AH23: =AG23 -> 0 | AI23: =AH23 -> 0 | AJ23: =AI23 -> 0 | AK23: =AJ23 -> 0 | AL23: =AK23 -> 0 | AM23: =AL23 -> 0 | AN23: =AM23 -> 0 | ... AQ23: =AP23 -> 0 | AR23: =SUM(AF23:AQ23) -> 0
C24: Printing (laser, inkjet) | D24: 0 | E24: =D24 -> 0 | F24: =E24 -> 0 | G24: =F24 -> 0 | H24: =G24 -> 0 | I24: =H24 -> 0 | J24: =I24 -> 0 | K24: =J24 -> 0 | L24: =K24 -> 0 | ... O24: =N24 -> 0 | P24: =SUM(D24:O24) -> 0 | R24: =O24 -> 0 | S24: =R24 -> 0 | T24: =S24 -> 0 | U24: =T24 -> 0 | V24: =U24 -> 0 | W24: =V24 -> 0 | X24: =W24 -> 0 | Y24: =X24 -> 0 | Z24: =Y24 -> 0 | ... AC24: =AB24 -> 0 | AD24: =SUM(R24:AC24) -> 0 | AF24: =AC24 -> 0 | AG24: =AF24 -> 0 | AH24: =AG24 -> 0 | AI24: =AH24 -> 0 | AJ24: =AI24 -> 0 | AK24: =AJ24 -> 0 | AL24: =AK24 -> 0 | AM24: =AL24 -> 0 | AN24: =AM24 -> 0 | ... AQ24: =AP24 -> 0 | AR24: =SUM(AF24:AQ24) -> 0
C25: Computer rental | D25: 0 | E25: =D25 -> 0 | F25: =E25 -> 0 | G25: =F25 -> 0 | H25: =G25 -> 0 | I25: =H25 -> 0 | J25: =I25 -> 0 | K25: =J25 -> 0 | L25: =K25 -> 0 | ... O25: =N25 -> 0 | P25: =SUM(D25:O25) -> 0 | R25: =O25 -> 0 | S25: =R25 -> 0 | T25: =S25 -> 0 | U25: =T25 -> 0 | V25: =U25 -> 0 | W25: =V25 -> 0 | X25: =W25 -> 0 | Y25: =X25 -> 0 | Z25: =Y25 -> 0 | ... AC25: =AB25 -> 0 | AD25: =SUM(R25:AC25) -> 0 | AF25: =AC25 -> 0 | AG25: =AF25 -> 0 | AH25: =AG25 -> 0 | AI25: =AH25 -> 0 | AJ25: =AI25 -> 0 | AK25: =AJ25 -> 0 | AL25: =AK25 -> 0 | AM25: =AL25 -> 0 | AN25: =AM25 -> 0 | ... AQ25: =AP25 -> 0 | AR25: =SUM(AF25:AQ25) -> 0
C26: Word processing | D26: 0 | E26: =D26 -> 0 | F26: =E26 -> 0 | G26: =F26 -> 0 | H26: =G26 -> 0 | I26: =H26 -> 0 | J26: =I26 -> 0 | K26: =J26 -> 0 | L26: =K26 -> 0 | ... O26: =N26 -> 0 | P26: =SUM(D26:O26) -> 0 | R26: =O26 -> 0 | S26: =R26 -> 0 | T26: =S26 -> 0 | U26: =T26 -> 0 | V26: =U26 -> 0 | W26: =V26 -> 0 | X26: =W26 -> 0 | Y26: =X26 -> 0 | Z26: =Y26 -> 0 | ... AC26: =AB26 -> 0 | AD26: =SUM(R26:AC26) -> 0 | AF26: =AC26 -> 0 | AG26: =AF26 -> 0 | AH26: =AG26 -> 0 | AI26: =AH26 -> 0 | AJ26: =AI26 -> 0 | AK26: =AJ26 -> 0 | AL26: =AK26 -> 0 | AM26: =AL26 -> 0 | AN26: =AM26 -> 0 | ... AQ26: =AP26 -> 0 | AR26: =SUM(AF26:AQ26) -> 0
C27: Desk top publishing | D27: 0 | E27: =D27 -> 0 | F27: =E27 -> 0 | G27: =F27 -> 0 | H27: =G27 -> 0 | I27: =H27 -> 0 | J27: =I27 -> 0 | K27: =J27 -> 0 | L27: =K27 -> 0 | ... O27: =N27 -> 0 | P27: =SUM(D27:O27) -> 0 | R27: =O27 -> 0 | S27: =R27 -> 0 | T27: =S27 -> 0 | U27: =T27 -> 0 | V27: =U27 -> 0 | W27: =V27 -> 0 | X27: =W27 -> 0 | Y27: =X27 -> 0 | Z27: =Y27 -> 0 | ... AC27: =AB27 -> 0 | AD27: =SUM(R27:AC27) -> 0 | AF27: =AC27 -> 0 | AG27: =AF27 -> 0 | AH27: =AG27 -> 0 | AI27: =AH27 -> 0 | AJ27: =AI27 -> 0 | AK27: =AJ27 -> 0 | AL27: =AK27 -> 0 | AM27: =AL27 -> 0 | AN27: =AM27 -> 0 | ... AQ27: =AP27 -> 0 | AR27: =SUM(AF27:AQ27) -> 0
C28: Newsletter production | D28: 0 | E28: =D28 -> 0 | F28: =E28 -> 0 | G28: =F28 -> 0 | H28: =G28 -> 0 | I28: =H28 -> 0 | J28: =I28 -> 0 | K28: =J28 -> 0 | L28: =K28 -> 0 | ... O28: =N28 -> 0 | P28: =SUM(D28:O28) -> 0 | R28: =O28 -> 0 | S28: =R28 -> 0 | T28: =S28 -> 0 | U28: =T28 -> 0 | V28: =U28 -> 0 | W28: =V28 -> 0 | X28: =W28 -> 0 | Y28: =X28 -> 0 | Z28: =Y28 -> 0 | ... AC28: =AB28 -> 0 | AD28: =SUM(R28:AC28) -> 0 | AF28: =AC28 -> 0 | AG28: =AF28 -> 0 | AH28: =AG28 -> 0 | AI28: =AH28 -> 0 | AJ28: =AI28 -> 0 | AK28: =AJ28 -> 0 | AL28: =AK28 -> 0 | AM28: =AL28 -> 0 | AN28: =AM28 -> 0 | ... AQ28: =AP28 -> 0 | AR28: =SUM(AF28:AQ28) -> 0
C29: Consulting services | D29: 0 | E29: =D29 -> 0 | F29: =E29 -> 0 | G29: =F29 -> 0 | H29: =G29 -> 0 | I29: =H29 -> 0 | J29: =I29 -> 0 | K29: =J29 -> 0 | L29: =K29 -> 0 | ... O29: =N29 -> 0 | P29: =SUM(D29:O29) -> 0 | R29: =O29 -> 0 | S29: =R29 -> 0 | T29: =S29 -> 0 | U29: =T29 -> 0 | V29: =U29 -> 0 | W29: =V29 -> 0 | X29: =W29 -> 0 | Y29: =X29 -> 0 | Z29: =Y29 -> 0 | ... AC29: =AB29 -> 0 | AD29: =SUM(R29:AC29) -> 0 | AF29: =AC29 -> 0 | AG29: =AF29 -> 0 | AH29: =AG29 -> 0 | AI29: =AH29 -> 0 | AJ29: =AI29 -> 0 | AK29: =AJ29 -> 0 | AL29: =AK29 -> 0 | AM29: =AL29 -> 0 | AN29: =AM29 -> 0 | ... AQ29: =AP29 -> 0 | AR29: =SUM(AF29:AQ29) -> 0
... C36: Other (replace with description) | D36: 0 | E36: =D36 -> 0 | F36: =E36 -> 0 | G36: =F36 -> 0 | H36: =G36 -> 0 | I36: =H36 -> 0 | J36: =I36 -> 0 | K36: =J36 -> 0 | L36: =K36 -> 0 | ... O36: =N36 -> 0 | P36: =SUM(D36:O36) -> 0 | R36: =O36 -> 0 | S36: =R36 -> 0 | T36: =S36 -> 0 | U36: =T36 -> 0 | V36: =U36 -> 0 | W36: =V36 -> 0 | X36: =W36 -> 0 | Y36: =X36 -> 0 | Z36: =Y36 -> 0 | ... AC36: =AB36 -> 0 | AD36: =SUM(R36:AC36) -> 0 | AF36: =AC36 -> 0 | AG36: =AF36 -> 0 | AH36: =AG36 -> 0 | AI36: =AH36 -> 0 | AJ36: =AI36 -> 0 | AK36: =AJ36 -> 0 | AL36: =AK36 -> 0 | AM36: =AL36 -> 0 | AN36: =AM36 -> 0 | ... AQ36: =AP36 -> 0 | AR36: =SUM(AF36:AQ36) -> 0
P37: =SUM(D37:O37) -> 0
B38: Total Operating Revenues | D38: =SUM(D18:D37) -> 0 | E38: =SUM(E18:E37) -> 0 | F38: =SUM(F18:F37) -> 0 | G38: =SUM(G18:G37) -> 0 | H38: =SUM(H18:H37) -> 0 | I38: =SUM(I18:I37) -> 0 | J38: =SUM(J18:J37) -> 0 | K38: =SUM(K18:K37) -> 0 | ... O38: =SUM(O18:O37) -> 0 | P38: =SUM(D38:O38) -> 0 | R38: =SUM(R18:R37) -> 0 | S38: =SUM(S18:S37) -> 0 | T38: =SUM(T18:T37) -> 0 | U38: =SUM(U18:U37) -> 0 | V38: =SUM(V18:V37) -> 0 | W38: =SUM(W18:W37) -> 0 | X38: =SUM(X18:X37) -> 0 | Y38: =SUM(Y18:Y37) -> 0 | ... AC38: =SUM(AC18:AC37) -> 0 | AD38: =SUM(R38:AC38) -> 0 | AF38: =SUM(AF18:AF37) -> 0 | AG38: =SUM(AG18:AG37) -> 0 | AH38: =SUM(AH18:AH37) -> 0 | AI38: =SUM(AI18:AI37) -> 0 | AJ38: =SUM(AJ18:AJ37) -> 0 | AK38: =SUM(AK18:AK37) -> 0 | AL38: =SUM(AL18:AL37) -> 0 | AM38: =SUM(AM18:AM37) -> 0 | ... AQ38: =SUM(AQ18:AQ37) -> 0 | AR38: =SUM(AF38:AQ38) -> 0
A40: Cash Outflows:
B41: Purchase of Assets:
C42: Vehicle | D42: 0 | P42: =SUM(D42:O42) -> 0 | AD42: =SUM(R42:AC42) -> 0 | AR42: =SUM(AF42:AQ42) -> 0
C43: Computers | D43: 0 | P43: =SUM(D43:O43) -> 0 | AD43: =SUM(R43:AC43) -> 0 | AR43: =SUM(AF43:AQ43) -> 0
C44: Computer peripherals | D44: 0 | P44: =SUM(D44:O44) -> 0 | AD44: =SUM(R44:AC44) -> 0 | AR44: =SUM(AF44:AQ44) -> 0
C45: Computer network | P45: =SUM(D45:O45) -> 0 | AD45: =SUM(R45:AC45) -> 0 | AR45: =SUM(AF45:AQ45) -> 0
C46: Software | D46: 0 | P46: =SUM(D46:O46) -> 0 | AD46: =SUM(R46:AC46) -> 0 | AR46: =SUM(AF46:AQ46) -> 0
C47: Photocopier | D47: 0 | P47: =SUM(D47:O47) -> 0 | AD47: =SUM(R47:AC47) -> 0 | AR47: =SUM(AF47:AQ47) -> 0
C48: Office equipment | D48: 0 | P48: =SUM(D48:O48) -> 0 | AD48: =SUM(R48:AC48) -> 0 | AR48: =SUM(AF48:AQ48) -> 0
C49: Furniture | D49: 0 | P49: =SUM(D49:O49) -> 0 | AD49: =SUM(R49:AC49) -> 0 | AR49: =SUM(AF49:AQ49) -> 0
...

Sheet Personnel
C2: Personnel Costs
I4: Year 1 | U4: Year 2 | AK4: Year 3
D5: Month 1 | E5: Month 2 | F5: Month 3 | G5: Month 4 | H5: Month 5 | I5: Month 6 | J5: Month 7 | K5: Month 8 | L5: Month 9 | M5: Month 10 | N5: Month 11 | O5: Month 12 | P5: Yr 1 Total | R5: Month 13 | S5: Month 14 | T5: Month 15 | U5: Month 16 | V5: Month 17 | W5: Month 18 | X5: Month 19 | Y5: Month 20 | Z5: Month 21 | AA5: Month 22 | AB5: Month 23 | AC5: Month 24 | AD5: Yr 2 Total | AF5: Month 25 | AG5: Month 26 | AH5: Month 27 | AI5: Month 28 | AJ5: Month 29 | AK5: Month 30 | AL5: Month 31 | AM5: Month 32 | AN5: Month 33 | AO5: Month 34 | AP5: Month 35 | AQ5: Month 36 | AR5: Yr 3 Total
B6: Salaries:
C7: Telecentre Manager | D7: 0 | E7: =D7 -> 0 | F7: =E7 -> 0 | G7: =F7 -> 0 | H7: =G7 -> 0 | I7: =H7 -> 0 | J7: =I7 -> 0 | K7: =J7 -> 0 | L7: =K7 -> 0 | ... O7: =N7 -> 0 | P7: =SUM(D7:O7) -> 0 | R7: =O7 -> 0 | S7: =R7 -> 0 | T7: =S7 -> 0 | U7: =T7 -> 0 | V7: =U7 -> 0 | W7: =V7 -> 0 | X7: =W7 -> 0 | Y7: =X7 -> 0 | Z7: =Y7 -> 0 | ... AC7: =AB7 -> 0 | AD7: =SUM(R7:AC7) -> 0 | AF7: =AC7 -> 0 | AG7: =AF7 -> 0 | AH7: =AG7 -> 0 | AI7: =AH7 -> 0 | AJ7: =AI7 -> 0 | AK7: =AJ7 -> 0 | AL7: =AK7 -> 0 | AM7: =AL7 -> 0 | AN7: =AM7 -> 0 | ... AQ7: =AP7 -> 0 | AR7: =SUM(AF7:AQ7) -> 0
C8: Assistant/Receptionist | D8: 0 | E8: =D8 -> 0 | F8: =E8 -> 0 | G8: =F8 -> 0 | H8: =G8 -> 0 | I8: =H8 -> 0 | J8: =I8 -> 0 | K8: =J8 -> 0 | L8: =K8 -> 0 | ... O8: =N8 -> 0 | P8: =SUM(D8:O8) -> 0 | R8: =O8 -> 0 | S8: =R8 -> 0 | T8: =S8 -> 0 | U8: =T8 -> 0 | V8: =U8 -> 0 | W8: =V8 -> 0 | X8: =W8 -> 0 | Y8: =X8 -> 0 | Z8: =Y8 -> 0 | ... AC8: =AB8 -> 0 | AD8: =SUM(R8:AC8) -> 0 | AF8: =AC8 -> 0 | AG8: =AF8 -> 0 | AH8: =AG8 -> 0 | AI8: =AH8 -> 0 | AJ8: =AI8 -> 0 | AK8: =AJ8 -> 0 | AL8: =AK8 -> 0 | AM8: =AL8 -> 0 | AN8: =AM8 -> 0 | ... AQ8: =AP8 -> 0 | AR8: =SUM(AF8:AQ8) -> 0
C9: Marketing Co-Ordinator | D9: 0 | E9: =D9 -> 0 | F9: =E9 -> 0 | G9: =F9 -> 0 | H9: =G9 -> 0 | I9: =H9 -> 0 | J9: =I9 -> 0 | K9: =J9 -> 0 | L9: =K9 -> 0 | ... O9: =N9 -> 0 | P9: =SUM(D9:O9) -> 0 | R9: =O9 -> 0 | S9: =R9 -> 0 | T9: =S9 -> 0 | U9: =T9 -> 0 | V9: =U9 -> 0 | W9: =V9 -> 0 | X9: =W9 -> 0 | Y9: =X9 -> 0 | Z9: =Y9 -> 0 | ... AC9: =AB9 -> 0 | AD9: =SUM(R9:AC9) -> 0 | AF9: =AC9 -> 0 | AG9: =AF9 -> 0 | AH9: =AG9 -> 0 | AI9: =AH9 -> 0 | AJ9: =AI9 -> 0 | AK9: =AJ9 -> 0 | AL9: =AK9 -> 0 | AM9: =AL9 -> 0 | AN9: =AM9 -> 0 | ... AQ9: =AP9 -> 0 | AR9: =SUM(AF9:AQ9) -> 0
C10: Trainer 1 | D10: 0 | E10: =D10 -> 0 | F10: =E10 -> 0 | G10: =F10 -> 0 | H10: =G10 -> 0 | I10: =H10 -> 0 | J10: =I10 -> 0 | K10: =J10 -> 0 | L10: =K10 -> 0 | ... O10: =N10 -> 0 | P10: =SUM(D10:O10) -> 0 | R10: =O10 -> 0 | S10: =R10 -> 0 | T10: =S10 -> 0 | U10: =T10 -> 0 | V10: =U10 -> 0 | W10: =V10 -> 0 | X10: =W10 -> 0 | Y10: =X10 -> 0 | Z10: =Y10 -> 0 | ... AC10: =AB10 -> 0 | AD10: =SUM(R10:AC10) -> 0 | AF10: =AC10 -> 0 | AG10: =AF10 -> 0 | AH10: =AG10 -> 0 | AI10: =AH10 -> 0 | AJ10: =AI10 -> 0 | AK10: =AJ10 -> 0 | AL10: =AK10 -> 0 | AM10: =AL10 -> 0 | AN10: =AM10 -> 0 | ... AQ10: =AP10 -> 0 | AR10: =SUM(AF10:AQ10) -> 0
C11: Trainer 2 | D11: 0 | E11: =D11 -> 0 | F11: =E11 -> 0 | G11: =F11 -> 0 | H11: =G11 -> 0 | I11: =H11 -> 0 | J11: =I11 -> 0 | K11: =J11 -> 0 | L11: =K11 -> 0 | ... O11: =N11 -> 0 | P11: =SUM(D11:O11) -> 0 | R11: =O11 -> 0 | S11: =R11 -> 0 | T11: =S11 -> 0 | U11: =T11 -> 0 | V11: =U11 -> 0 | W11: =V11 -> 0 | X11: =W11 -> 0 | Y11: =X11 -> 0 | Z11: =Y11 -> 0 | ... AC11: =AB11 -> 0 | AD11: =SUM(R11:AC11) -> 0 | AF11: =AC11 -> 0 | AG11: =AF11 -> 0 | AH11: =AG11 -> 0 | AI11: =AH11 -> 0 | AJ11: =AI11 -> 0 | AK11: =AJ11 -> 0 | AL11: =AK11 -> 0 | AM11: =AL11 -> 0 | AN11: =AM11 -> 0 | ... AQ11: =AP11 -> 0 | AR11: =SUM(AF11:AQ11) -> 0
C12: Technician 1 | D12: 0 | E12: =2 -> 2 | F12: =E12 -> 2 | G12: =F12 -> 2 | H12: =G12 -> 2 | I12: =H12 -> 2 | J12: =I12 -> 2 | K12: =J12 -> 2 | L12: =K12 -> 2 | M12: =L12 -> 2 | ... O12: =N12 -> 2 | P12: =SUM(D12:O12) -> 22 | R12: =O12 -> 2 | S12: =R12 -> 2 | T12: =S12 -> 2 | U12: =T12 -> 2 | V12: =U12 -> 2 | W12: =V12 -> 2 | X12: =W12 -> 2 | Y12: =X12 -> 2 | Z12: =Y12 -> 2 | ... AC12: =AB12 -> 2 | AD12: =SUM(R12:AC12) -> 24 | AF12: =AC12 -> 2 | AG12: =AF12 -> 2 | AH12: =AG12 -> 2 | AI12: =AH12 -> 2 | AJ12: =AI12 -> 2 | AK12: =AJ12 -> 2 | AL12: =AK12 -> 2 | AM12: =AL12 -> 2 | AN12: =AM12 -> 2 | ... AQ12: =AP12 -> 2 | AR12: =SUM(AF12:AQ12) -> 24
C13: Technician 2 | D13: 0 | E13: =D13 -> 0 | F13: =E13 -> 0 | G13: =F13 -> 0 | H13: =G13 -> 0 | I13: =H13 -> 0 | J13: =I13 -> 0 | K13: =J13 -> 0 | L13: =K13 -> 0 | ... O13: =N13 -> 0 | P13: =SUM(D13:O13) -> 0 | R13: =O13 -> 0 | S13: =R13 -> 0 | T13: =S13 -> 0 | U13: =T13 -> 0 | V13: =U13 -> 0 | W13: =V13 -> 0 | X13: =W13 -> 0 | Y13: =X13 -> 0 | Z13: =Y13 -> 0 | ... AC13: =AB13 -> 0 | AD13: =SUM(R13:AC13) -> 0 | AF13: =AC13 -> 0 | AG13: =AF13 -> 0 | AH13: =AG13 -> 0 | AI13: =AH13 -> 0 | AJ13: =AI13 -> 0 | AK13: =AJ13 -> 0 | AL13: =AK13 -> 0 | AM13: =AL13 -> 0 | AN13: =AM13 -> 0 | ... AQ13: =AP13 -> 0 | AR13: =SUM(AF13:AQ13) -> 0
B15: Total Salaries | D15: =SUM(D7:D14) -> 0 | E15: =SUM(E7:E14) -> 2 | F15: =SUM(F7:F14) -> 2 | G15: =SUM(G7:G14) -> 2 | H15: =SUM(H7:H14) -> 2 | I15: =SUM(I7:I14) -> 2 | J15: =SUM(J7:J14) -> 2 | K15: =SUM(K7:K14) -> 2 | ... O15: =SUM(O7:O14) -> 2 | P15: =SUM(D15:O15) -> 22 | R15: =SUM(R7:R14) -> 2 | S15: =SUM(S7:S14) -> 2 | T15: =SUM(T7:T14) -> 2 | U15: =SUM(U7:U14) -> 2 | V15: =SUM(V7:V14) -> 2 | W15: =SUM(W7:W14) -> 2 | X15: =SUM(X7:X14) -> 2 | Y15: =SUM(Y7:Y14) -> 2 | ... AC15: =SUM(AC7:AC14) -> 2 | AD15: =SUM(R15:AC15) -> 24 | AF15: =SUM(AF7:AF14) -> 2 | AG15: =SUM(AG7:AG14) -> 2 | AH15: =SUM(AH7:AH14) -> 2 | AI15: =SUM(AI7:AI14) -> 2 | AJ15: =SUM(AJ7:AJ14) -> 2 | AK15: =SUM(AK7:AK14) -> 2 | AL15: =SUM(AL7:AL14) -> 2 | AM15: =SUM(AM7:AM14) -> 2 | ... AQ15: =SUM(AQ7:AQ14) -> 2 | AR15: =SUM(AF15:AQ15) -> 24
B17: Overhead percentage | D17: 0 | E17: =D17 -> 0 | F17: =E17 -> 0 | G17: =F17 -> 0 | H17: =G17 -> 0 | I17: =H17 -> 0 | J17: =I17 -> 0 | K17: =J17 -> 0 | L17: =K17 -> 0 | ... O17: =N17 -> 0 | R17: =O17 -> 0 | S17: =R17 -> 0 | T17: =S17 -> 0 | U17: =T17 -> 0 | V17: =U17 -> 0 | W17: =V17 -> 0 | X17: =W17 -> 0 | Y17: =X17 -> 0 | Z17: =Y17 -> 0 | ... AC17: =AB17 -> 0 | AF17: =AC17 -> 0 | AG17: =AF17 -> 0 | AH17: =AG17 -> 0 | AI17: =AH17 -> 0 | AJ17: =AI17 -> 0 | AK17: =AJ17 -> 0 | AL17: =AK17 -> 0 | AM17: =AL17 -> 0 | AN17: =AM17 -> 0 | ... AQ17: =AP17 -> 0
B18: Overhead costs | D18: =D15*D17 -> 0 | E18: =E15*E17 -> 0 | F18: =F15*F17 -> 0 | G18: =G15*G17 -> 0 | H18: =H15*H17 -> 0 | I18: =I15*I17 -> 0 | J18: =J15*J17 -> 0 | K18: =K15*K17 -> 0 | ... O18: =O15*O17 -> 0 | R18: =R15*R17 -> 0 | S18: =S15*S17 -> 0 | T18: =T15*T17 -> 0 | U18: =U15*U17 -> 0 | V18: =V15*V17 -> 0 | W18: =W15*W17 -> 0 | X18: =X15*X17 -> 0 | Y18: =Y15*Y17 -> 0 | ... AC18: =AC15*AC17 -> 0 | AF18: =AF15*AF17 -> 0 | AG18: =AG15*AG17 -> 0 | AH18: =AH15*AH17 -> 0 | AI18: =AI15*AI17 -> 0 | AJ18: =AJ15*AJ17 -> 0 | AK18: =AK15*AK17 -> 0 | AL18: =AL15*AL17 -> 0 | AM18: =AM15*AM17 -> 0 | ... AQ18: =AQ15*AQ17 -> 0
B20: Total Personnel Costs | D20: =D15+D18 -> 0 | E20: =E15+E18 -> 2 | F20: =F15+F18 -> 2 | G20: =G15+G18 -> 2 | H20: =H15+H18 -> 2 | I20: =I15+I18 -> 2 | J20: =J15+J18 -> 2 | K20: =K15+K18 -> 2 | ... O20: =O15+O18 -> 2 | P20: =SUM(D20:O20) -> 22 | R20: =R15+R18 -> 2 | S20: =S15+S18 -> 2 | T20: =T15+T18 -> 2 | U20: =U15+U18 -> 2 | V20: =V15+V18 -> 2 | W20: =W15+W18 -> 2 | X20: =X15+X18 -> 2 | Y20: =Y15+Y18 -> 2 | ... AC20: =AC15+AC18 -> 2 | AD20: =SUM(R20:AC20) -> 24 | AF20: =AF15+AF18 -> 2 | AG20: =AG15+AG18 -> 2 | AH20: =AH15+AH18 -> 2 | AI20: =AI15+AI18 -> 2 | AJ20: =AJ15+AJ18 -> 2 | AK20: =AK15+AK18 -> 2 | AL20: =AL15+AL18 -> 2 | AM20: =AM15+AM18 -> 2 | ... AQ20: =AQ15+AQ18 -> 2 | AR20: =SUM(AF20:AQ20) -> 24

Sheet In-Kind Contributions
C2: ='Cash Flows'!C2 -> Telecentre Name
C3: In-Kind Contributions
C4: Years 1-3
I5: Year 1 | U5: Year 2 | AK5: Year 3
D6: Month 1 | E6: Month 2 | F6: Month 3 | G6: Month 4 | H6: Month 5 | I6: Month 6 | J6: Month 7 | K6: Month 8 | L6: Month 9 | M6: Month 10 | N6: Month 11 | O6: Month 12 | P6: Yr 1 Total | R6: Month 13 | S6: Month 14 | T6: Month 15 | U6: Month 16 | V6: Month 17 | W6: Month 18 | X6: Month 19 | Y6: Month 20 | Z6: Month 21 | AA6: Month 22 | AB6: Month 23 | AC6: Month 24 | AD6: Yr 2 Total | AF6: Month 25 | AG6: Month 26 | AH6: Month 27 | AI6: Month 28 | AJ6: Month 29 | AK6: Month 30 | AL6: Month 31 | AM6: Month 32 | AN6: Month 33 | AO6: Month 34 | AP6: Month 35 | AQ6: Month 36 | AR6: Yr 3 Total
A8: Contribution of Assets:
C9: Vehicle | D9: 0 | P9: =SUM(D9:O9) -> 0 | AD9: =SUM(R9:AC9) -> 0 | AR9: =SUM(AF9:AQ9) -> 0
C10: Computers | D10: 0 | P10: =SUM(D10:O10) -> 0 | AD10: =SUM(R10:AC10) -> 0 | AR10: =SUM(AF10:AQ10) -> 0
C11: Computer peripherals | D11: 0 | P11: =SUM(D11:O11) -> 0 | AD11: =SUM(R11:AC11) -> 0 | AR11: =SUM(AF11:AQ11) -> 0
C12: Computer network | D12: 0 | P12: =SUM(D12:O12) -> 0 | AD12: =SUM(R12:AC12) -> 0 | AR12: =SUM(AF12:AQ12) -> 0
C13: Software | D13: 0 | P13: =SUM(D13:O13) -> 0 | AD13: =SUM(R13:AC13) -> 0 | AR13: =SUM(AF13:AQ13) -> 0
C14: Photocopier | D14: 0 | P14: =SUM(D14:O14) -> 0 | AD14: =SUM(R14:AC14) -> 0 | AR14: =SUM(AF14:AQ14) -> 0
C15: Office equipment | D15: 0 | P15: =SUM(D15:O15) -> 0 | AD15: =SUM(R15:AC15) -> 0 | AR15: =SUM(AF15:AQ15) -> 0
C16: Furniture | D16: 0 | P16: =SUM(D16:O16) -> 0 | AD16: =SUM(R16:AC16) -> 0 | AR16: =SUM(AF16:AQ16) -> 0
C17: Leasehold improvements | D17: 0 | P17: =SUM(D17:O17) -> 0 | AD17: =SUM(R17:AC17) -> 0 | AR17: =SUM(AF17:AQ17) -> 0
C18: Satellite dish | D18: 0 | P18: =SUM(D18:O18) -> 0 | AD18: =SUM(R18:AC18) -> 0 | AR18: =SUM(AF18:AQ18) -> 0
P19: =SUM(D19:O19) -> 0 | AD19: =SUM(R19:AC19) -> 0 | AR19: =SUM(AF19:AQ19) -> 0
A20: Total Asset Contributions | D20: =SUM(D9:D19) -> 0 | E20: =SUM(E9:E19) -> 0 | F20: =SUM(F9:F19) -> 0 | G20: =SUM(G9:G19) -> 0 | H20: =SUM(H9:H19) -> 0 | I20: =SUM(I9:I19) -> 0 | J20: =SUM(J9:J19) -> 0 | K20: =SUM(K9:K19) -> 0 | ... O20: =SUM(O9:O19) -> 0 | P20: =SUM(D20:O20) -> 0 | R20: =SUM(R9:R19) -> 0 | S20: =SUM(S9:S19) -> 0 | T20: =SUM(T9:T19) -> 0 | U20: =SUM(U9:U19) -> 0 | V20: =SUM(V9:V19) -> 0 | W20: =SUM(W9:W19) -> 0 | X20: =SUM(X9:X19) -> 0 | Y20: =SUM(Y9:Y19) -> 0 | ... AC20: =SUM(AC9:AC19) -> 0 | AD20: =SUM(R20:AC20) -> 0 | AF20: =SUM(AF9:AF19) -> 0 | AG20: =SUM(AG9:AG19) -> 0 | AH20: =SUM(AH9:AH19) -> 0 | AI20: =SUM(AI9:AI19) -> 0 | AJ20: =SUM(AJ9:AJ19) -> 0 | AK20: =SUM(AK9:AK19) -> 0 | AL20: =SUM(AL9:AL19) -> 0 | AM20: =SUM(AM9:AM19) -> 0 | ... AQ20: =SUM(AQ9:AQ19) -> 0 | AR20: =SUM(AF20:AQ20) -> 0
A22: Contributions Displacing Operating Costs:
C23: Personnel costs (from Personnel sheet) | D23: 0 | E23: =D23 -> 0 | F23: =E23 -> 0 | G23: =F23 -> 0 | H23: =G23 -> 0 | I23: =H23 -> 0 | J23: =I23 -> 0 | K23: =J23 -> 0 | L23: =K23 -> 0 | ... O23: =N23 -> 0 | P23: =SUM(D23:O23) -> 0 | R23: =Q23 -> 0 | S23: =R23 -> 0 | T23: =S23 -> 0 | U23: =T23 -> 0 | V23: =U23 -> 0 | W23: =V23 -> 0 | X23: =W23 -> 0 | Y23: =X23 -> 0 | ... AC23: =AB23 -> 0 | AD23: =SUM(R23:AC23) -> 0 | AF23: =AE23 -> 0 | AG23: =AF23 -> 0 | AH23: =AG23 -> 0 | AI23: =AH23 -> 0 | AJ23: =AI23 -> 0 | AK23: =AJ23 -> 0 | AL23: =AK23 -> 0 | AM23: =AL23 -> 0 | ... AQ23: =AP23 -> 0 | AR23: =SUM(AF23:AQ23) -> 0
C24: Vehicle operating costs | D24: 0 | E24: =D24 -> 0 | F24: =E24 -> 0 | G24: =F24 -> 0 | H24: =G24 -> 0 | I24: =H24 -> 0 | J24: =I24 -> 0 | K24: =J24 -> 0 | L24: =K24 -> 0 | ... O24: =N24 -> 0 | P24: =SUM(D24:O24) -> 0 | R24: =O24 -> 0 | S24: =R24 -> 0 | T24: =S24 -> 0 | U24: =T24 -> 0 | V24: =U24 -> 0 | W24: =V24 -> 0 | X24: =W24 -> 0 | Y24: =X24 -> 0 | Z24: =Y24 -> 0 | ... AC24: =AB24 -> 0 | AD24: =SUM(R24:AC24) -> 0 | AF24: =AC24 -> 0 | AG24: =AF24 -> 0 | AH24: =AG24 -> 0 | AI24: =AH24 -> 0 | AJ24: =AI24 -> 0 | AK24: =AJ24 -> 0 | AL24: =AK24 -> 0 | AM24: =AL24 -> 0 | AN24: =AM24 -> 0 | ... AQ24: =AP24 -> 0 | AR24: =SUM(AF24:AQ24) -> 0
C25: Consulting services | D25: 0 | E25: =D25 -> 0 | F25: =E25 -> 0 | G25: =F25 -> 0 | H25: =G25 -> 0 | I25: =H25 -> 0 | J25: =I25 -> 0 | K25: =J25 -> 0 | L25: =K25 -> 0 | ... O25: =N25 -> 0 | P25: =SUM(D25:O25) -> 0 | R25: =O25 -> 0 | S25: =R25 -> 0 | T25: =S25 -> 0 | U25: =T25 -> 0 | V25: =U25 -> 0 | W25: =V25 -> 0 | X25: =W25 -> 0 | Y25: =X25 -> 0 | Z25: =Y25 -> 0 | ... AC25: =AB25 -> 0 | AD25: =SUM(R25:AC25) -> 0 | AF25: =AC25 -> 0 | AG25: =AF25 -> 0 | AH25: =AG25 -> 0 | AI25: =AH25 -> 0 | AJ25: =AI25 -> 0 | AK25: =AJ25 -> 0 | AL25: =AK25 -> 0 | AM25: =AL25 -> 0 | AN25: =AM25 -> 0 | ... AQ25: =AP25 -> 0 | AR25: =SUM(AF25:AQ25) -> 0
C26: Rent | D26: 0 | E26: =D26 -> 0 | F26: =E26 -> 0 | G26: =F26 -> 0 | H26: =G26 -> 0 | I26: =H26 -> 0 | J26: =I26 -> 0 | K26: =J26 -> 0 | L26: =K26 -> 0 | ... O26: =N26 -> 0 | P26: =SUM(D26:O26) -> 0 | R26: =O26 -> 0 | S26: =R26 -> 0 | T26: =S26 -> 0 | U26: =T26 -> 0 | V26: =U26 -> 0 | W26: =V26 -> 0 | X26: =W26 -> 0 | Y26: =X26 -> 0 | Z26: =Y26 -> 0 | ... AC26: =AB26 -> 0 | AD26: =SUM(R26:AC26) -> 0 | AF26: =AC26 -> 0 | AG26: =AF26 -> 0 | AH26: =AG26 -> 0 | AI26: =AH26 -> 0 | AJ26: =AI26 -> 0 | AK26: =AJ26 -> 0 | AL26: =AK26 -> 0 | AM26: =AL26 -> 0 | AN26: =AM26 -> 0 | ... AQ26: =AP26 -> 0 | AR26: =SUM(AF26:AQ26) -> 0
C27: Equipment leases | D27: 0 | E27: =D27 -> 0 | F27: =E27 -> 0 | G27: =F27 -> 0 | H27: =G27 -> 0 | I27: =H27 -> 0 | J27: =I27 -> 0 | K27: =J27 -> 0 | L27: =K27 -> 0 | ... O27: =N27 -> 0 | P27: =SUM(D27:O27) -> 0 | R27: =O27 -> 0 | S27: =R27 -> 0 | T27: =S27 -> 0 | U27: =T27 -> 0 | V27: =U27 -> 0 | W27: =V27 -> 0 | X27: =W27 -> 0 | Y27: =X27 -> 0 | Z27: =Y27 -> 0 | ... AC27: =AB27 -> 0 | AD27: =SUM(R27:AC27) -> 0 | AF27: =AC27 -> 0 | AG27: =AF27 -> 0 | AH27: =AG27 -> 0 | AI27: =AH27 -> 0 | AJ27: =AI27 -> 0 | AK27: =AJ27 -> 0 | AL27: =AK27 -> 0 | AM27: =AL27 -> 0 | AN27: =AM27 -> 0 | ... AQ27: =AP27 -> 0 | AR27: =SUM(AF27:AQ27) -> 0
C28: Electricity | D28: 0 | E28: =D28 -> 0 | F28: =E28 -> 0 | G28: =F28 -> 0 | H28: =G28 -> 0 | I28: =H28 -> 0 | J28: =I28 -> 0 | K28: =J28 -> 0 | L28: =K28 -> 0 | ... O28: =N28 -> 0 | P28: =SUM(D28:O28) -> 0 | R28: =O28 -> 0 | S28: =R28 -> 0 | T28: =S28 -> 0 | U28: =T28 -> 0 | V28: =U28 -> 0 | W28: =V28 -> 0 | X28: =W28 -> 0 | Y28: =X28 -> 0 | Z28: =Y28 -> 0 | ... AC28: =AB28 -> 0 | AD28: =SUM(R28:AC28) -> 0 | AF28: =AC28 -> 0 | AG28: =AF28 -> 0 | AH28: =AG28 -> 0 | AI28: =AH28 -> 0 | AJ28: =AI28 -> 0 | AK28: =AJ28 -> 0 | AL28: =AK28 -> 0 | AM28: =AL28 -> 0 | AN28: =AM28 -> 0 | ... AQ28: =AP28 -> 0 | AR28: =SUM(AF28:AQ28) -> 0
C29: Telephone | D29: 0 | E29: =D29 -> 0 | F29: =E29 -> 0 | G29: =F29 -> 0 | H29: =G29 -> 0 | I29: =H29 -> 0 | J29: =I29 -> 0 | K29: =J29 -> 0 | L29: =K29 -> 0 | ... O29: =N29 -> 0 | P29: =SUM(D29:O29) -> 0 | R29: =O29 -> 0 | S29: =R29 -> 0 | T29: =S29 -> 0 | U29: =T29 -> 0 | V29: =U29 -> 0 | W29: =V29 -> 0 | X29: =W29 -> 0 | Y29: =X29 -> 0 | Z29: =Y29 -> 0 | ... AC29: =AB29 -> 0 | AD29: =SUM(R29:AC29) -> 0 | AF29: =AC29 -> 0 | AG29: =AF29 -> 0 | AH29: =AG29 -> 0 | AI29: =AH29 -> 0 | AJ29: =AI29 -> 0 | AK29: =AJ29 -> 0 | AL29: =AK29 -> 0 | AM29: =AL29 -> 0 | AN29: =AM29 -> 0 | ... AQ29: =AP29 -> 0 | AR29: =SUM(AF29:AQ29) -> 0
C30: Internet connection | D30: 0 | E30: =D30 -> 0 | F30: =E30 -> 0 | G30: =F30 -> 0 | H30: =G30 -> 0 | I30: =H30 -> 0 | J30: =I30 -> 0 | K30: =J30 -> 0 | L30: =K30 -> 0 | ... O30: =N30 -> 0 | P30: =SUM(D30:O30) -> 0 | R30: =O30 -> 0 | S30: =R30 -> 0 | T30: =S30 -> 0 | U30: =T30 -> 0 | V30: =U30 -> 0 | W30: =V30 -> 0 | X30: =W30 -> 0 | Y30: =X30 -> 0 | Z30: =Y30 -> 0 | ... AC30: =AB30 -> 0 | AD30: =SUM(R30:AC30) -> 0 | AF30: =AC30 -> 0 | AG30: =AF30 -> 0 | AH30: =AG30 -> 0 | AI30: =AH30 -> 0 | AJ30: =AI30 -> 0 | AK30: =AJ30 -> 0 | AL30: =AK30 -> 0 | AM30: =AL30 -> 0 | AN30: =AM30 -> 0 | ... AQ30: =AP30 -> 0 | AR30: =SUM(AF30:AQ30) -> 0
C31: Postage and Courier | D31: 0 | E31: =D31 -> 0 | F31: =E31 -> 0 | G31: =F31 -> 0 | H31: =G31 -> 0 | I31: =H31 -> 0 | J31: =I31 -> 0 | K31: =J31 -> 0 | L31: =K31 -> 0 | ... O31: =N31 -> 0 | P31: =SUM(D31:O31) -> 0 | R31: =O31 -> 0 | S31: =R31 -> 0 | T31: =S31 -> 0 | U31: =T31 -> 0 | V31: =U31 -> 0 | W31: =V31 -> 0 | X31: =W31 -> 0 | Y31: =X31 -> 0 | Z31: =Y31 -> 0 | ... AC31: =AB31 -> 0 | AD31: =SUM(R31:AC31) -> 0 | AF31: =AC31 -> 0 | AG31: =AF31 -> 0 | AH31: =AG31 -> 0 | AI31: =AH31 -> 0 | AJ31: =AI31 -> 0 | AK31: =AJ31 -> 0 | AL31: =AK31 -> 0 | AM31: =AL31 -> 0 | AN31: =AM31 -> 0 | ... AQ31: =AP31 -> 0 | AR31: =SUM(AF31:AQ31) -> 0
C32: Water | D32: 0 | E32: =D32 -> 0 | F32: =E32 -> 0 | G32: =F32 -> 0 | H32: =G32 -> 0 | I32: =H32 -> 0 | J32: =I32 -> 0 | K32: =J32 -> 0 | L32: =K32 -> 0 | ... O32: =N32 -> 0 | P32: =SUM(D32:O32) -> 0 | R32: =O32 -> 0 | S32: =R32 -> 0 | T32: =S32 -> 0 | U32: =T32 -> 0 | V32: =U32 -> 0 | W32: =V32 -> 0 | X32: =W32 -> 0 | Y32: =X32 -> 0 | Z32: =Y32 -> 0 | ... AC32: =AB32 -> 0 | AD32: =SUM(R32:AC32) -> 0 | AF32: =AC32 -> 0 | AG32: =AF32 -> 0 | AH32: =AG32 -> 0 | AI32: =AH32 -> 0 | AJ32: =AI32 -> 0 | AK32: =AJ32 -> 0 | AL32: =AK32 -> 0 | AM32: =AL32 -> 0 | AN32: =AM32 -> 0 | ... AQ32: =AP32 -> 0 | AR32: =SUM(AF32:AQ32) -> 0
C33: Equipment maintenance | D33: 0 | E33: =D33 -> 0 | F33: =E33 -> 0 | G33: =F33 -> 0 | H33: =G33 -> 0 | I33: =H33 -> 0 | J33: =I33 -> 0 | K33: =J33 -> 0 | L33: =K33 -> 0 | ... O33: =N33 -> 0 | P33: =SUM(D33:O33) -> 0 | R33: =O33 -> 0 | S33: =R33 -> 0 | T33: =S33 -> 0 | U33: =T33 -> 0 | V33: =U33 -> 0 | W33: =V33 -> 0 | X33: =W33 -> 0 | Y33: =X33 -> 0 | Z33: =Y33 -> 0 | ... AC33: =AB33 -> 0 | AD33: =SUM(R33:AC33) -> 0 | AF33: =AC33 -> 0 | AG33: =AF33 -> 0 | AH33: =AG33 -> 0 | AI33: =AH33 -> 0 | AJ33: =AI33 -> 0 | AK33: =AJ33 -> 0 | AL33: =AK33 -> 0 | AM33: =AL33 -> 0 | AN33: =AM33 -> 0 | ... AQ33: =AP33 -> 0 | AR33: =SUM(AF33:AQ33) -> 0
C34: Software upgrades | D34: 0 | E34: =D34 -> 0 | F34: =E34 -> 0 | G34: =F34 -> 0 | H34: =G34 -> 0 | I34: =H34 -> 0 | J34: =I34 -> 0 | K34: =J34 -> 0 | L34: =K34 -> 0 | ... O34: =N34 -> 0 | P34: =SUM(D34:O34) -> 0 | R34: =O34 -> 0 | S34: =R34 -> 0 | T34: =S34 -> 0 | U34: =T34 -> 0 | V34: =U34 -> 0 | W34: =V34 -> 0 | X34: =W34 -> 0 | Y34: =X34 -> 0 | Z34: =Y34 -> 0 | ... AC34: =AB34 -> 0 | AD34: =SUM(R34:AC34) -> 0 | AF34: =AC34 -> 0 | AG34: =AF34 -> 0 | AH34: =AG34 -> 0 | AI34: =AH34 -> 0 | AJ34: =AI34 -> 0 | AK34: =AJ34 -> 0 | AL34: =AK34 -> 0 | AM34: =AL34 -> 0 | AN34: =AM34 -> 0 | ... AQ34: =AP34 -> 0 | AR34: =SUM(AF34:AQ34) -> 0
C35: Insurance | D35: 0 | E35: =D35 -> 0 | F35: =E35 -> 0 | G35: =F35 -> 0 | H35: =G35 -> 0 | I35: =H35 -> 0 | J35: =I35 -> 0 | K35: =J35 -> 0 | L35: =K35 -> 0 | ... O35: =N35 -> 0 | P35: =SUM(D35:O35) -> 0 | R35: =O35 -> 0 | S35: =R35 -> 0 | T35: =S35 -> 0 | U35: =T35 -> 0 | V35: =U35 -> 0 | W35: =V35 -> 0 | X35: =W35 -> 0 | Y35: =X35 -> 0 | Z35: =Y35 -> 0 | ... AC35: =AB35 -> 0 | AD35: =SUM(R35:AC35) -> 0 | AF35: =AC35 -> 0 | AG35: =AF35 -> 0 | AH35: =AG35 -> 0 | AI35: =AH35 -> 0 | AJ35: =AI35 -> 0 | AK35: =AJ35 -> 0 | AL35: =AK35 -> 0 | AM35: =AL35 -> 0 | AN35: =AM35 -> 0 | ... AQ35: =AP35 -> 0 | AR35: =SUM(AF35:AQ35) -> 0
... C45: Goods for resale | D45: 0 | E45: =D45 -> 0 | F45: =E45 -> 0 | G45: =F45 -> 0 | H45: =G45 -> 0 | I45: =H45 -> 0 | J45: =I45 -> 0 | K45: =J45 -> 0 | L45: =K45 -> 0 | ... O45: =N45 -> 0 | P45: =SUM(D45:O45) -> 0 | R45: =O45 -> 0 | S45: =R45 -> 0 | T45: =S45 -> 0 | U45: =T45 -> 0 | V45: =U45 -> 0 | W45: =V45 -> 0 | X45: =W45 -> 0 | Y45: =X45 -> 0 | Z45: =Y45 -> 0 | ... AC45: =AB45 -> 0 | AD45: =SUM(R45:AC45) -> 0 | AF45: =AC45 -> 0 | AG45: =AF45 -> 0 | AH45: =AG45 -> 0 | AI45: =AH45 -> 0 | AJ45: =AI45 -> 0 | AK45: =AJ45 -> 0 | AL45: =AK45 -> 0 | AM45: =AL45 -> 0 | AN45: =AM45 -> 0 | ... AQ45: =AP45 -> 0 | AR45: =SUM(AF45:AQ45) -> 0
P46: =SUM(D46:O46) -> 0 | AD46: =SUM(R46:AC46) -> 0 | AR46: =SUM(AF46:AQ46) -> 0
A47: Total Contributions Displacing Operating Costs: | D47: =SUM(D23:D46) -> 0 | E47: =SUM(E23:E46) -> 0 | F47: =SUM(F23:F46) -> 0 | G47: =SUM(G23:G46) -> 0 | H47: =SUM(H23:H46) -> 0 | I47: =SUM(I23:I46) -> 0 | J47: =SUM(J23:J46) -> 0 | K47: =SUM(K23:K46) -> 0 | ... O47: =SUM(O23:O46) -> 0 | P47: =SUM(D47:O47) -> 0 | R47: =SUM(R23:R46) -> 0 | S47: =SUM(S23:S46) -> 0 | T47: =SUM(T23:T46) -> 0 | U47: =SUM(U23:U46) -> 0 | V47: =SUM(V23:V46) -> 0 | W47: =SUM(W23:W46) -> 0 | X47: =SUM(X23:X46) -> 0 | Y47: =SUM(Y23:Y46) -> 0 | ... AC47: =SUM(AC23:AC46) -> 0 | AD47: =SUM(R47:AC47) -> 0 | AF47: =SUM(AF23:AF46) -> 0 | AG47: =SUM(AG23:AG46) -> 0 | AH47: =SUM(AH23:AH46) -> 0 | AI47: =SUM(AI23:AI46) -> 0 | AJ47: =SUM(AJ23:AJ46) -> 0 | AK47: =SUM(AK23:AK46) -> 0 | AL47: =SUM(AL23:AL46) -> 0 | AM47: =SUM(AM23:AM46) -> 0 | ... AQ47: =SUM(AQ23:AQ46) -> 0 | AR47: =SUM(AF47:AQ47) -> 0

Sheet Financial Summary
C2: ='Cash Flows'!C2 -> Telecentre Name
C3: Financial Summary
C4: Years 1-3
C6: Year 1 | D6: Year 2 | E6: Year 3
A8: In-Kind Contributions
B9: Contribution of Assets | C9: ='In-Kind Contributions'!P20 -> 0 | D9: ='In-Kind Contributions'!AD20 -> 0 | E9: ='In-Kind Contributions'!AR20 -> 0
B10: Contributions displacing operating costs | C10: ='In-Kind Contributions'!P47 -> 0 | D10: ='In-Kind Contributions'!AD47 -> 0 | E10: ='In-Kind Contributions'!AR47 -> 0
A11: Total In-Kind Contributions | C11: =SUM(C9:C10) -> 0 | D11: =SUM(D9:D10) -> 0 | E11: =SUM(E9:E10) -> 0
A14: Cash Flows:
A16: Cash Inflows:
B17: Total Financing Cash Flows | C17: ='Cash Flows'!P15 -> 0 | D17: ='Cash Flows'!AD15 -> 0 | E17: ='Cash Flows'!AR15 -> 0
B18: Revenue From Operations | C18: ='Cash Flows'!P38 -> 0 | D18: ='Cash Flows'!AD38 -> 0 | E18: ='Cash Flows'!AR38 -> 0
A19: Total Cash Inflows | C19: =SUM(C17:C18) -> 0 | D19: =SUM(D17:D18) -> 0 | E19: =SUM(E17:E18) -> 0
A21: Cash Outflows:
B22: Purchase of Assets | C22: ='Cash Flows'!P53 -> 0 | D22: ='Cash Flows'!AD53 -> 0 | E22: ='Cash Flows'!AR53 -> 0
B23: Operating Expenses | C23: ='Cash Flows'!P83 -> 22 | D23: ='Cash Flows'!AD83 -> 24 | E23: ='Cash Flows'!AR83 -> 24
A24: Total Cash Outflows | C24: =SUM(C22:C23) -> 22 | D24: =SUM(D22:D23) -> 24 | E24: =SUM(E22:E23) -> 24
A26: Net Cash Flow | C26: =C19-C24 -> -22 | D26: =D19-D24 -> -24 | E26: =E19-E24 -> -24
A28: Less Reserve for Capital Replacement | C28: ='Cash Flows'!P89 -> 0 | D28: ='Cash Flows'!AD89 -> 0 | E28: ='Cash Flows'!AR89 -> 0
A30: Unallocated Cash at Year End | C30: =C26-C28 -> -22 | D30: =C30+D26-D28 -> -46 | E30: =D30+E26-E28 -> -70
