Workbook

Sheet Financial summary
M1: 6 months
C2: 1998 | E2: 1999 | G2: 2000 | I2: 2001 | K2: 2002 | M2: 2003
A4: Beginning Cash Balance | C4: 15023.53 | E4: =C33 -> 13204.939 | G4: =E33 -> 69161.819 | I4: =G33 -> 58643.279 | K4: =I33 -> 53651.229 | M4: =K33 -> 55257.059 | O4: Note by WFDF interim treasurer Juha Jalovaara on 07/04/2003: Attention! Please note that the figures for 2001 have been restated compared to the material presented at Congress 2002. 2001 now shows a net loss of $4992.05 instead of the previously stated loss of $492.05. This discrepancy was discovered shortly before Congress 2002 and discussed but not resolved there. It is now resolved in this statement. The problem was due to an error in transferring data while moving between two bookkeeping systems.
A6: Income
B7: Dues | C7: 1705.26 | E7: 2496 | G7: 3684.14 | I7: 3110 | K7: 5354.09 | M7: 6542
B8: Special Sponsorship | C8: 0 | E8: 55000 | F8: 5 | G8: 0 | I8: 0 | K8: 0
B9: Sanctioning 2 | C9: 12391.57 | E9: 8907.66 | G9: 1655.09 | I9: 7398 | K9: 16360
B10: Sponsorship | C10: 0 | E10: 4000 | F10: 6 | G10: 0 | I10: 0 | K10: 0
B11: Donations | C11: 0 | E11: 0 | G11: 0 | I11: 2000 | K11: 5506 | M11: 500
B12: Interest | C12: 232.90954 | E12: 0 | G12: 64.79 | I12: 762.45 | K12: 340.16 | M12: 69.09
B13: Sales and Other Income | C13: 2388.57 | E13: 0 | G13: 0 | I13: 1062 | K13: 5014 | L13: a
B15: Total Income | C15: =SUM(C6:C13) -> 16718.31 | E15: =SUM(E6:E13) -> 70403.66 | G15: =SUM(G6:G13) -> 5404.02 | I15: =SUM(I6:I13) -> 14332.45 | K15: =SUM(K6:K13) -> 32574.25 | M15: =SUM(M6:M13) -> 7111.09
A18: Expenses
B19: Administration | C19: 2969.44 | E19: 9179.63 | F19: 7 | G19: 8797.44 | H19: 7 | I19: =8238.33 -> 8238.33 | J19: 7 | K19: 14000 | M19: 7014.09
B20: Bank Fees | C20: 336.27014 | E20: 0 | G20: 0 | I20: 200 | K20: 347.65 | M20: 134
B21: Events inc.travel | C21: 0 | E21: 1529.6 | G21: 1728.76 | I21: 8054.12 | K21: =8821.24+118.52 -> 8939.76 | L21: a | M21: 835.91
B22: Member Services | C22: 0 | E22: 872.07 | G22: 459.37 | I22: 447.17 | K22: 2875.88
B23: Memberships 3 | C23: 2234.55 | E23: 2797.25 | G23: 4784.49 | I23: 2384.88 | K23: 2313.2 | M23: 2884.8
B24: Other Fees | C24: 12996.64 | D24: 4 | E24: 0 | G24: 0 | I24: 0 | K24: 491.93
B25: Outreach | C25: 0 | E25: 68.23 | G25: 152.5 | I25: 0 | K25: 2000
B27: Total Expense | C27: =SUM(C19:C25) -> 18536.9 | E27: =SUM(E19:E25) -> 14446.78 | G27: =SUM(G19:G25) -> 15922.56 | I27: =SUM(I19:I25) -> 19324.5 | K27: =SUM(K19:K25) -> 30968.42 | M27: =SUM(M19:M25) -> 10868.8
A30: Net Income/ (Loss) | C30: =C15-C27 -> -1818.5906 | E30: =E15-E27 -> 55956.88 | G30: =G15-G27 -> -10518.54 | I30: =I15-I27 -> -4992.05 | K30: =K15-K27 -> 1605.83 | M30: =M15-M27 -> -3757.71
A33: Ending Cash/Inv. Balance | C33: =C4+C30 -> 13204.939 | E33: =E4+E30 -> 69161.819 | G33: =G4+G30 -> 58643.279 | I33: =I4+I30 -> 53651.229 | K33: =K4+K30 -> 55257.059 | M33: =M4+M30 -> 51499.349
B35: Checking Account | C35: =C33 -> 13204.939 | E35: 69161.82 | G35: 8578.49 | I35: 12823.99 | K35: 14326.7 | M35: 10525.9
B36: Money Market | C36: 0 | E36: 0 | G36: 50064.79 | I36: 40827.24 | K36: 41167.4 | M36: 41210.49
B37: Loan to Event Organizer | C37: 0 | E37: 0 | G37: 0 | I37: 0 | K37: 0 | M37: 0
A39: Difference | C39: =C33-SUM(C35:C37) -> 0 | E39: =E33-SUM(E35:E37) -> -0.00059479554 | G39: =G33-SUM(G35:G37) -> -0.00059479553 | I39: =I33-SUM(I35:I37) -> -0.00059479552 | K39: =K33-SUM(K35:K37) -> -237.04059 | M39: =M33-SUM(M35:M37) -> -237.04059
A41: Notes
A42: 1 | B42: Statement prepared under cash basis accounting; certain accounts have been reclassified on a historical basis for consistency.
A43: 2 | B43: Sanctioning fees charged to participants at WFDF events of approximately US$7.50 per person; events include: 1998 WUGC;
B44: 1999 WUCC/WOC; 2000 WUGC; 2001 World Games/WOC.
A45: 3 | B45: Fees for GAISF and IWGA memberships.
A46: 4 | B46: Fees of SEK 80,673 (US$10,000) for _______ and US$3,000 for ______.
A47: 5 | B47: Sponsorship from Worldsport.com (now defunct).
A48: 6 | B48: Sponsorship from Innova and Wham-O.
A49: 7 | B49: Administrative Expenses includes part-time salary of US$ 6,000 p.a. in 1999-2001 and US$ 12,000 p.a. in 2002.
A50: a | B50: Includes loan of US$5,000 to 2002 WUCC organizers. Repayment shows in sales and income, payment in Events.
A51: 9 | B51: Represents grant to NEFA for Juniors program.

Sheet Balance Sheet
E1: Dec 31, '99 | F1: Dec 31, '00 | G1: Dec 31, '01 | H1: Dec 31, '02
A2: ASSETS
B3: Current Assets
C4: Total Checking/Savings | E4: 69161.82 | F4: 8578.49 | G4: 12323.99 | H4: ='Financial summary'!K35 -> 14326.7
C5: Money Market (Savings) | E5: 0 | F5: 50064.79 | G5: 40827.24 | H5: ='Financial summary'!K36 -> 41167.4
D6: Total Current Assets | E6: =E4+E5 -> 69161.82 | F6: =F4+F5 -> 58643.28 | G6: =G4+G5 -> 53151.23 | H6: =H4+H5 -> 55494.1
A7: TOTAL ASSETS | E7: =ROUND(E2+E6,5) -> 69161.82 | F7: =ROUND(F2+F6,5) -> 58643.28 | G7: =ROUND(G2+G6,5) -> 53151.23 | H7: =ROUND(H2+H6,5) -> 55494.1
A9: LIABILITIES & EQUITY
B10: Equity
C11: Opening Bal Equity | E11: 5481.15 | F11: 5481.15 | G11: 5481.15 | H11: 5481.15
C12: Retained Earnings | E12: 0 | F12: 63680.67 | G12: 53162.13 | H12: =G12+G13 -> 48170.08
C13: Net Income | E13: 63680.67 | F13: -10518.54 | G13: ='Financial summary'!I30 -> -4992.05 | H13: ='Financial summary'!K30 -> 1605.83
D14: Total Equity | E14: =ROUND(SUM(E10:E13),5) -> 69161.82 | F14: =ROUND(SUM(F10:F13),5) -> 58643.28 | G14: =ROUND(SUM(G10:G13),5) -> 53651.23 | H14: =ROUND(SUM(H10:H13),5) -> 55257.06
A15: TOTAL LIABILITIES & EQUITY | E15: =ROUND(E9+E14,5) -> 69161.82 | F15: =ROUND(F9+F14,5) -> 58643.28 | G15: =ROUND(G9+G14,5) -> 53651.23 | H15: =ROUND(H9+H14,5) -> 55257.06

Sheet Stork - 2002 Expenditures
A1: WFDF 2002 Statement of Receipts and Expenditures | F1: (sheet 2) | G1: rev. 7/3/03
A3: Expenditures
A4: Date | B4: Type | C4: Total Expended | D4: Fees | E4: memo | F4: Administration | G4: memo | H4: Events | I4: memo | J4: Mem Serv. | K4: memo | L4: Dues | M4: memo | N4: Services | O4: memo | P4: Marketing | Q4: memo | R4: Sp. Projects | S4: memo | T4: Other | U4: memo
A6: 37263 | B6: ck 1340 | C6: 25.58 | T6: 25.58 | U6: UPA pc
A7: 37263 | B7: ck 1335 | C7: 5000 | H7: 5000 | I7: WUCC Loan
A8: 37285 | B8: ck 1341 | C8: 500 | H8: 500 | I8: P. Eriksson WG
A9: 37300 | B9: Bk transfer | C9: 306.8 | L9: 306.8 | M9: IWGA 2002
A10: 37300 | B10: Bk fee | C10: 42 | D10: 42 | E10: Payment fee
A11: 37301 | B11: Bk transfer | C11: 2006.4 | L11: 2006.4 | M11: GAISF 2002
A12: 37301 | B12: Bk fee | C12: 42 | D12: 42 | E12: Payment fee
A13: 37307 | B13: Bk fee | C13: 10 | D13: 10 | E13: Dues transfer fee
A14: 37307 | B14: Bk fee | C14: 10 | D14: 10 | E14: Dues transfer fee
A15: 37308 | B15: Bk fee | C15: 10 | D15: 10 | E15: Dues transfer fee
A16: 37350 | B16: ck 1343 | C16: 40 | N16: 40 | O16: Fr. Range Internet
A17: 37351 | B17: Bk fee | C17: 10 | D17: 10 | E17: Dues transfer fee
A18: 37354 | B18: ck 1342 | C18: 52.54 | N18: 52.54 | O18: B. Wright Internet
A19: 37356 | B19: Bk fee | C19: 10 | D19: 10 | E19: Dues transfer fee
A20: 37356 | B20: Bk fee | C20: 10 | D20: 10 | E20: Dues transfer fee
A21: 37356 | B21: ck 1344 | C21: 3000 | F21: 3000 | G21: DR Q1 ED fee
A22: 37365 | B22: Bk fee | C22: 1.5 | D22: 1.5 | E22: Dues transfer fee
A23: 37377 | B23: Bk fee | C23: 10 | D23: 10 | E23: Dues transfer fee
A24: 37378 | B24: Bk fee | C24: 10 | D24: 10 | E24: Dues transfer fee
A25: 37378 | B25: Bk fee | C25: 10 | D25: 10 | E25: Dues transfer fee
A26: 37392 | B26: Bk fee | C26: 10 | D26: 10 | E26: Dues transfer fee
A27: 37405 | B27: ck 1346 | C27: 2000 | R27: 2000 | S27: Jr. Grant NEFA
A28: 37407 | B28: Bk fee | C28: 10 | D28: 10 | E28: Dues transfer fee
A29: 37418 | B29: Bk fee | C29: 10 | D29: 10 | E29: Dues transfer fee
A30: 37427 | B30: Bk fee | C30: 10 | D30: 10 | E30: Dues transfer fee
A31: 37442 | B31: Bk fee | C31: 10 | D31: 10 | E31: Dues transfer fee
A32: 37445 | B32: ck 1348 | C32: 3000 | F32: 3000 | G32: DR Q2 ED fee
A33: 37453 | B33: ck 1349 | C33: 650 | H33: 650 | I33: DR Cong Exp
A34: 37456 | B34: Bk transfer | C34: 609.82 | H34: 609.82 | I34: Medal engrav
A35: 37456 | B35: Bk fee | C35: 42 | D35: 42 | E35: Payment fee
A36: 37468 | B36: ck 1350 | C36: 2024.48 | E36: Cash from DR to JG | F36: 2000 | G36: CM01/02fees | T36: 24.48 | U36: Pet. Cash BW
A37: 37468 | B37: Bk fee | C37: 10 | D37: 10 | E37: Payment fee
A38: 37470 | B38: ck 1347 | C38: 1000 | N38: 1000 | O38: D&O Insurance
A39: 37476 | B39: Bk fee | C39: 54.15 | D39: 54.15 | E39: Medal pmt. foul up
A40: 37496 | B40: ck 1351 | C40: 1045.43 | N40: 1045.43 | O40: Cong Facil. Exp.
A41: 37502 | B41: ck 1354 | C41: 441.87 | T41: 441.87 | U41: BW Con Print
A42: 37503 | B42: auto wd | C42: 416.73 | N42: 416.73 | O42: Fr. Range Internet
...

Sheet Stork - 2002 Receipts
A1: WFDF 2002 Statement of Receipts and Expenditures | F1: (sheet 1) | G1: rev. 7/3/03
A3: Receipts
A4: Date | B4: Type | C4: Total Received | D4: Dues | E4: memo | F4: Licensing | G4: memo | H4: Sanctioning | I4: memo | J4: Interest | K4: memo | L4: Donations | M4: memo | N4: Other | O4: memo
A6: 37307 | B6: Bk trans | C6: 573.23 | D6: 573.23 | E6: Norway 99/00/01/02
A7: 37308 | B7: Bk trans | C7: 290.86 | D7: 290.86 | E7: Norway credit
A8: 37341 | B8: Deposit | C8: 150 | D8: 150 | E8: Ireland (A) 01/02
A9: 37351 | B9: Bk trans | C9: 130 | D9: 130 | E9: Sweden 02 OK
A10: 37355 | B10: Deposit | C10: 2000 | L10: 2000 | M10: Titcomb Jrs.
A11: 37355 | B11: Deposit | C11: 300 | D11: 300 | E11: UPA (O) 02 OK | N11: 14 | O11: Petty cash
A12: 37355 | B12: Deposit | C12: 14
A13: 37355 | B13: Bk trans | C13: 150 | D13: 150 | E13: Belgium 02
A14: 37356 | B14: Bk trans | C14: 300 | D14: 300 | E14: France 01/02
A15: 37356 | B15: Bk trans | C15: 75 | D15: 75 | E15: Spain 02
A16: 37364 | B16: Deposit | C16: 150 | D16: 150 | E16: Canada 02
A17: 37364 | B17: Deposit | C17: 250 | D17: 250 | E17: PDGA 99/00/01/02
A18: 37369 | B18: Deposit | C18: 150 | D18: 150 | E18: Brazil (A) 01/02
A19: 37369 | B19: Deposit | C19: 150 | D19: 150 | E19: Japan 02
A20: 37369 | B20: Deposit | C20: 150 | D20: 150 | E20: Mexico 02
A21: 37370 | B21: Bk trans | C21: 150 | D21: 150 | E21: UK O2
A22: 37377 | B22: Bk trans | C22: 300 | D22: 300 | E22: Australia 01/02
A23: 37378 | B23: Bk trans | C23: 150 | D23: 150 | E23: Germany 02
A24: 37378 | B24: Bk trans | C24: 125 | D24: 125 | E24: CZ Republic 02 OK
... A27: 37392 | B27: Bk trans | C27: 150 | D27: 150 | E27: Denmark 02
A28: 37396 | B28: Deposit | C28: 5000 | N28: 5000 | O28: WUCC 02 Repay
A29: 37407 | B29: Deposit | C29: 250 | D29: 250 | E29: FPA 99/00/01/02 OK
A30: 37407 | B30: Bk trans | C30: 150 | D30: 150 | E30: Switzerland 02
A31: 37414 | B31: Deposit | C31: 300 | D31: 300 | E31: Austrla 01/02
A32: 37414 | B32: Deposit | C32: 150 | D32: 150 | E32: Hong Kong 02
A33: 37418 | B33: Bk trans | C33: 150 | D33: 150 | E33: Italy 02
A34: 37427 | B34: Bk trans | C34: 135 | D34: 135 | E34: ROC O2 OK
A35: 37442 | B35: Bk trans | C35: 75 | D35: 75 | E35: Russia (A) PE
A36: 37468 | B36: Bk trans | C36: 1360 | H36: 1360 | I36: Latvia Jrs.
A37: 37519 | B37: Deposit | C37: 3000 | L37: 3000 | M37: UPA Grant
A38: 37586 | B38: Deposit | C38: 150 | D38: 150 | E38: Venezuela 02
A39: 37599 | B39: Deposit | C39: 15000 | H39: 15000 | I39: WUCC 2002
A40: 37621 | B40: Deposit | C40: 506 | L40: 506 | M40: Finland*
A41: 37621 | B41: Bk trans | C41: 340.16 | J41: 340.16 | K41: MM int.
A43: Totals | C43: =SUM(C6:C42) -> 32574.25 | D43: =SUM(D6:D42) -> 5354.09 | F43: =SUM(F6:F42) -> 0 | H43: =SUM(H6:H42) -> 16360 | J43: =SUM(J6:J42) -> 340.16 | L43: =SUM(L6:L42) -> 5506 | N43: =SUM(N6:N42) -> 5014
