Workbook

Sheet Occupancy
B2: This worksheet presents a series of schedules for modeling the sensible and latent heat gain from occupants.
B3: Each of the sets of schedules leads to equivalent annual heat gain, but contain varying levels of detail.
B5: All of the schedules are built up from the most detailed level, found on tab "Occ L3-WD-DU-LR".
B17: Schedule assumptions:
C19: Living Area Sensible Gain: | F19: 230 | G19: BTU/person/hr
C20: Bedroom Area Sensible Gain: | F20: 210 | G20: BTU/person/hr
C22: Living Area Latent Gain: | F22: 190 | G22: BTU/person/hr
C23: Bedroom Area Latent Gain: | F23: 140 | G23: BTU/person/hr
C26: For a simulation year of 2000: | F26: days | G26: fraction
C27: Annual:
E28: no. of weekday - day use: | F28: 125 | G28: =+F28/365 -> 0.34246575
E29: no. of weekend - day use: | F29: 57 | G29: =+F29/365 -> 0.15616438
E30: no. of weekday - no day use: | F30: 126 | G30: =+F30/365 -> 0.34520548
E31: no. of weekend - no day use: | F31: 57 | G31: =+F31/365 -> 0.15616438
C33: Fraction of Weekend/Holidays: | F33: =+(F29+F31)/SUM(F28:F31) -> 0.31232877
C34: Fraction of Weekdays: | F34: =+(F28+F30)/SUM(F28:F31) -> 0.68767123
C35: Fraction DayUse: | F35: =(F28+F29)/SUM(F28:F31) -> 0.49863014
C36: Fraction NoDayUse: | F36: =(F30+F31)/SUM(F28:F31) -> 0.50136986
C38: Sum of Living Area Occ Sch: | F38: =SUM('Occ L1-LR'!C16:C39) -> 7.9845338
C39: Sum of Bedroom Occ Sch: | F39: =SUM('Occ L1-LR'!D16:D39) -> 8.5392603

Sheet Occ L0
B2: Schedule Type: | D2: Occupancy | F2: Notes: | G2: This is the simplest occupancy schedule, and is appropriate to single-zone models.
B3: Detail Level: | D3: 0
B8: Occupancy Schedule, where number of people = number of bedrooms
C9: Sensible load per person = | F9: =+(Occupancy!F19*Occupancy!F38+Occupancy!F20*Occupancy!F39)/(Occupancy!F38+Occupancy!F39) -> 219.66429 | G9: BTU/hr/person | I9: (these values weighted by sum of Living area schedule and Bedroom area schedule)
C10: Latent load per person = | F10: =+(Occupancy!F22*Occupancy!F19+Occupancy!F23*Occupancy!F20)/(Occupancy!F19+Occupancy!F20) -> 166.13636 | G10: BTU/hr/person
C15: Occ
B16: 1 | C16: =+'Occ L1-WD'!C16*Occupancy!$F$34+'Occ L1-WD'!D16*Occupancy!$F$33 -> 1
B17: 2 | C17: =+'Occ L1-WD'!C17*Occupancy!$F$34+'Occ L1-WD'!D17*Occupancy!$F$33 -> 1
B18: 3 | C18: =+'Occ L1-WD'!C18*Occupancy!$F$34+'Occ L1-WD'!D18*Occupancy!$F$33 -> 1
B19: 4 | C19: =+'Occ L1-WD'!C19*Occupancy!$F$34+'Occ L1-WD'!D19*Occupancy!$F$33 -> 1
B20: 5 | C20: =+'Occ L1-WD'!C20*Occupancy!$F$34+'Occ L1-WD'!D20*Occupancy!$F$33 -> 1
B21: 6 | C21: =+'Occ L1-WD'!C21*Occupancy!$F$34+'Occ L1-WD'!D21*Occupancy!$F$33 -> 1
B22: 7 | C22: =+'Occ L1-WD'!C22*Occupancy!$F$34+'Occ L1-WD'!D22*Occupancy!$F$33 -> 1
B23: 8 | C23: =+'Occ L1-WD'!C23*Occupancy!$F$34+'Occ L1-WD'!D23*Occupancy!$F$33 -> 0.88309589
B24: 9 | C24: =+'Occ L1-WD'!C24*Occupancy!$F$34+'Occ L1-WD'!D24*Occupancy!$F$33 -> 0.40860957
B25: 10 | C25: =+'Occ L1-WD'!C25*Occupancy!$F$34+'Occ L1-WD'!D25*Occupancy!$F$33 -> 0.086151248
B26: 11 | C26: =+'Occ L1-WD'!C26*Occupancy!$F$34+'Occ L1-WD'!D26*Occupancy!$F$33 -> 0.24188778
B27: 12 | C27: =+'Occ L1-WD'!C27*Occupancy!$F$34+'Occ L1-WD'!D27*Occupancy!$F$33 -> 0.24188778
... B39: 24 | C39: =+'Occ L1-WD'!C39*Occupancy!$F$34+'Occ L1-WD'!D39*Occupancy!$F$33 -> 1
B41: Total hours/person | C41: =SUM(C16:C39) -> 16.368057
B45: DOE2.2 Schedule Format:
B47: $ Occupancy Schedule, average for all days of the year, all spaces
B48: =C15&"-DS"&" =DAY-SCHEDULE TYPE = FRACTION" -> Occ-DS =DAY-SCHEDULE TYPE = FRACTION
B49: ="(1,24) ("&TEXT(C16,"0.0000")&","&TEXT(C17,"0.0000")&","&TEXT(C18,"0.0000")&","&TEXT(C19,"0.0000")&","&TEXT(C20,"0.0000")&","&TEXT(C21,"0.0000")&","&TEXT(C22,"0.0000")&","&TEXT(C23,"0.0000")&"," -> #VALUE!
B50: =" "&TEXT(C24,"0.0000")&","&TEXT(C25,"0.0000")&","&TEXT(C26,"0.0000")&","&TEXT(C27,"0.0000")&","&TEXT(C28,"0.0000")&","&TEXT(C29,"0.0000")&","&TEXT(C30,"0.0000")&","&TEXT(C31,"0.0000")&"," -> #VALUE!
B51: =" "&TEXT(C32,"0.0000")&","&TEXT(C33,"0.0000")&","&TEXT(C34,"0.0000")&","&TEXT(C35,"0.0000")&","&TEXT(C36,"0.0000")&","&TEXT(C37,"0.0000")&","&TEXT(C38,"0.0000")&","&TEXT(C39,"0.0000")&") .." -> #VALUE!
B53: ="Occupancy-SCH =SCHEDULE TYPE = FRACTION" -> Occupancy-SCH =SCHEDULE TYPE = FRACTION
B54: =" THRU DEC 31 (ALL) "&C15&"-DS .." -> THRU DEC 31 (ALL) Occ-DS ..

Sheet Occ L1-WD
B2: Schedule Type: | D2: Occupancy | F2: Notes: | G2: This schedule distinguishes between weedays and weekends, and is appropriate to single-zone models.
B3: Detail Level: | D3: 1
B4: 1: | C4: Weekday | D4: Weekend
B8: Occupancy Schedule, where number of people = number of bedrooms
C9: Sensible load per person = | F9: =+(Occupancy!F19*Occupancy!F38+Occupancy!F20*Occupancy!F39)/(Occupancy!F38+Occupancy!F39) -> 219.66429 | G9: BTU/hr/person | I9: (these values weighted by sum of Living area schedule and Bedroom area schedule)
C10: Latent load per person = | F10: =+(Occupancy!F22*Occupancy!F19+Occupancy!F23*Occupancy!F20)/(Occupancy!F19+Occupancy!F20) -> 166.13636 | G10: BTU/hr/person
C14: Weekday | D14: Weekend
B15: hour | C15: Occ-WD | D15: Occ-WE
B16: 1 | C16: =+'OccL2-WD-DU'!C16*Occupancy!$F$35+'OccL2-WD-DU'!E16*Occupancy!$F$36 -> 1 | D16: =+'OccL2-WD-DU'!D16*Occupancy!$F$35+'OccL2-WD-DU'!F16*Occupancy!$F$36 -> 1
B17: 2 | C17: =+'OccL2-WD-DU'!C17*Occupancy!$F$35+'OccL2-WD-DU'!E17*Occupancy!$F$36 -> 1 | D17: =+'OccL2-WD-DU'!D17*Occupancy!$F$35+'OccL2-WD-DU'!F17*Occupancy!$F$36 -> 1
B18: 3 | C18: =+'OccL2-WD-DU'!C18*Occupancy!$F$35+'OccL2-WD-DU'!E18*Occupancy!$F$36 -> 1 | D18: =+'OccL2-WD-DU'!D18*Occupancy!$F$35+'OccL2-WD-DU'!F18*Occupancy!$F$36 -> 1
B19: 4 | C19: =+'OccL2-WD-DU'!C19*Occupancy!$F$35+'OccL2-WD-DU'!E19*Occupancy!$F$36 -> 1 | D19: =+'OccL2-WD-DU'!D19*Occupancy!$F$35+'OccL2-WD-DU'!F19*Occupancy!$F$36 -> 1
B20: 5 | C20: =+'OccL2-WD-DU'!C20*Occupancy!$F$35+'OccL2-WD-DU'!E20*Occupancy!$F$36 -> 1 | D20: =+'OccL2-WD-DU'!D20*Occupancy!$F$35+'OccL2-WD-DU'!F20*Occupancy!$F$36 -> 1
B21: 6 | C21: =+'OccL2-WD-DU'!C21*Occupancy!$F$35+'OccL2-WD-DU'!E21*Occupancy!$F$36 -> 1 | D21: =+'OccL2-WD-DU'!D21*Occupancy!$F$35+'OccL2-WD-DU'!F21*Occupancy!$F$36 -> 1
B22: 7 | C22: =+'OccL2-WD-DU'!C22*Occupancy!$F$35+'OccL2-WD-DU'!E22*Occupancy!$F$36 -> 1 | D22: =+'OccL2-WD-DU'!D22*Occupancy!$F$35+'OccL2-WD-DU'!F22*Occupancy!$F$36 -> 1
B23: 8 | C23: =+'OccL2-WD-DU'!C23*Occupancy!$F$35+'OccL2-WD-DU'!E23*Occupancy!$F$36 -> 0.83 | D23: =+'OccL2-WD-DU'!D23*Occupancy!$F$35+'OccL2-WD-DU'!F23*Occupancy!$F$36 -> 1
B24: 9 | C24: =+'OccL2-WD-DU'!C24*Occupancy!$F$35+'OccL2-WD-DU'!E24*Occupancy!$F$36 -> 0.28989041 | D24: =+'OccL2-WD-DU'!D24*Occupancy!$F$35+'OccL2-WD-DU'!F24*Occupancy!$F$36 -> 0.67
B25: 10 | C25: =+'OccL2-WD-DU'!C25*Occupancy!$F$35+'OccL2-WD-DU'!E25*Occupancy!$F$36 -> 0.12465753 | D25: =+'OccL2-WD-DU'!D25*Occupancy!$F$35+'OccL2-WD-DU'!F25*Occupancy!$F$36 -> 0.001369863
B26: 11 | C26: =+'OccL2-WD-DU'!C26*Occupancy!$F$35+'OccL2-WD-DU'!E26*Occupancy!$F$36 -> 0.12465753 | D26: =+'OccL2-WD-DU'!D26*Occupancy!$F$35+'OccL2-WD-DU'!F26*Occupancy!$F$36 -> 0.5
B27: 12 | C27: =+'OccL2-WD-DU'!C27*Occupancy!$F$35+'OccL2-WD-DU'!E27*Occupancy!$F$36 -> 0.12465753 | D27: =+'OccL2-WD-DU'!D27*Occupancy!$F$35+'OccL2-WD-DU'!F27*Occupancy!$F$36 -> 0.5
... B39: 24 | C39: =+'OccL2-WD-DU'!C39*Occupancy!$F$35+'OccL2-WD-DU'!E39*Occupancy!$F$36 -> 1 | D39: =+'OccL2-WD-DU'!D39*Occupancy!$F$35+'OccL2-WD-DU'!F39*Occupancy!$F$36 -> 1
B45: DOE2.2 Schedule Format:
B47: $ Occupancy Schedule, average for all WEEKDAYS of the year, all spaces
B48: =C15&"-DS"&" =DAY-SCHEDULE TYPE = FRACTION" -> Occ-WD-DS =DAY-SCHEDULE TYPE = FRACTION
B49: ="(1,24) ("&TEXT(C16,"0.0000")&","&TEXT(C17,"0.0000")&","&TEXT(C18,"0.0000")&","&TEXT(C19,"0.0000")&","&TEXT(C20,"0.0000")&","&TEXT(C21,"0.0000")&","&TEXT(C22,"0.0000")&","&TEXT(C23,"0.0000")&"," -> #VALUE!
B50: =" "&TEXT(C24,"0.0000")&","&TEXT(C25,"0.0000")&","&TEXT(C26,"0.0000")&","&TEXT(C27,"0.0000")&","&TEXT(C28,"0.0000")&","&TEXT(C29,"0.0000")&","&TEXT(C30,"0.0000")&","&TEXT(C31,"0.0000")&"," -> #VALUE!
B51: =" "&TEXT(C32,"0.0000")&","&TEXT(C33,"0.0000")&","&TEXT(C34,"0.0000")&","&TEXT(C35,"0.0000")&","&TEXT(C36,"0.0000")&","&TEXT(C37,"0.0000")&","&TEXT(C38,"0.0000")&","&TEXT(C39,"0.0000")&") .." -> #VALUE!
B53: $ Occupancy Schedule, average for all WEEKENDS and HOLIDAYS of the year, all spaces
B54: =D15&"-DS"&" =DAY-SCHEDULE TYPE = FRACTION" -> Occ-WE-DS =DAY-SCHEDULE TYPE = FRACTION
B55: ="(1,24) ("&TEXT(D16,"0.0000")&","&TEXT(D17,"0.0000")&","&TEXT(D18,"0.0000")&","&TEXT(D19,"0.0000")&","&TEXT(D20,"0.0000")&","&TEXT(D21,"0.0000")&","&TEXT(D22,"0.0000")&","&TEXT(D23,"0.0000")&"," -> #VALUE!
B56: =" "&TEXT(D24,"0.0000")&","&TEXT(D25,"0.0000")&","&TEXT(D26,"0.0000")&","&TEXT(D27,"0.0000")&","&TEXT(D28,"0.0000")&","&TEXT(D29,"0.0000")&","&TEXT(D30,"0.0000")&","&TEXT(D31,"0.0000")&"," -> #VALUE!
B57: =" "&TEXT(D32,"0.0000")&","&TEXT(D33,"0.0000")&","&TEXT(D34,"0.0000")&","&TEXT(D35,"0.0000")&","&TEXT(D36,"0.0000")&","&TEXT(D37,"0.0000")&","&TEXT(D38,"0.0000")&","&TEXT(D39,"0.0000")&") .." -> #VALUE!
B59: ="Occupancy-SCH =SCHEDULE TYPE = FRACTION" -> Occupancy-SCH =SCHEDULE TYPE = FRACTION
B60: =" THRU DEC 31 (WD) "&C15&"-DS" -> THRU DEC 31 (WD) Occ-WD-DS
B61: =" (WEH) "&D15&"-DS .." -> (WEH) Occ-WE-DS ..

Sheet Occ L1-DU
B2: Schedule Type: | D2: Occupancy | F2: Notes: | G2: This schedule distinguishes between Day-Use and Non-Day-Use family types, but does not differentiate weekdays
B3: Detail Level: | D3: 1 | G3: from weekends. Limited applicability.
B4: 1: | C4: Day Use | D4: NonDayUse
B8: Occupancy Schedule, where number of people = number of bedrooms
C9: Sensible load per person = | F9: =+(Occupancy!F19*Occupancy!F38+Occupancy!F20*Occupancy!F39)/(Occupancy!F38+Occupancy!F39) -> 219.66429 | G9: BTU/hr/person | I9: (these values weighted by sum of Living area schedule and Bedroom area schedule)
C10: Latent load per person = | F10: =+(Occupancy!F22*Occupancy!F19+Occupancy!F23*Occupancy!F20)/(Occupancy!F19+Occupancy!F20) -> 166.13636 | G10: BTU/hr/person
C14: Day Use | D14: NonDayUse
B15: hour | C15: Occ-DU | D15: Occ-ND
B16: 1 | C16: =+'OccL2-DU-LR'!C16+'OccL2-DU-LR'!D16 -> 1 | D16: =+'OccL2-DU-LR'!E16+'OccL2-DU-LR'!F16 -> 1
B17: 2 | C17: =+'OccL2-DU-LR'!C17+'OccL2-DU-LR'!D17 -> 1 | D17: =+'OccL2-DU-LR'!E17+'OccL2-DU-LR'!F17 -> 1
B18: 3 | C18: =+'OccL2-DU-LR'!C18+'OccL2-DU-LR'!D18 -> 1 | D18: =+'OccL2-DU-LR'!E18+'OccL2-DU-LR'!F18 -> 1
B19: 4 | C19: =+'OccL2-DU-LR'!C19+'OccL2-DU-LR'!D19 -> 1 | D19: =+'OccL2-DU-LR'!E19+'OccL2-DU-LR'!F19 -> 1
B20: 5 | C20: =+'OccL2-DU-LR'!C20+'OccL2-DU-LR'!D20 -> 1 | D20: =+'OccL2-DU-LR'!E20+'OccL2-DU-LR'!F20 -> 1
B21: 6 | C21: =+'OccL2-DU-LR'!C21+'OccL2-DU-LR'!D21 -> 1 | D21: =+'OccL2-DU-LR'!E21+'OccL2-DU-LR'!F21 -> 1
B22: 7 | C22: =+'OccL2-DU-LR'!C22+'OccL2-DU-LR'!D22 -> 1 | D22: =+'OccL2-DU-LR'!E22+'OccL2-DU-LR'!F22 -> 1
B23: 8 | C23: =+'OccL2-DU-LR'!C23+'OccL2-DU-LR'!D23 -> 0.88309589 | D23: =+'OccL2-DU-LR'!E23+'OccL2-DU-LR'!F23 -> 0.88309589
B24: 9 | C24: =+'OccL2-DU-LR'!C24+'OccL2-DU-LR'!D24 -> 0.43619178 | D24: =+'OccL2-DU-LR'!E24+'OccL2-DU-LR'!F24 -> 0.38117808
B25: 10 | C25: =+'OccL2-DU-LR'!C25+'OccL2-DU-LR'!D25 -> 0.32808219 | D25: =+'OccL2-DU-LR'!E25+'OccL2-DU-LR'!F25 -> 0.15616438
B26: 11 | C26: =+'OccL2-DU-LR'!C26+'OccL2-DU-LR'!D26 -> 0.32808219 | D26: =+'OccL2-DU-LR'!E26+'OccL2-DU-LR'!F26 -> 0.15616438
B27: 12 | C27: =+'OccL2-DU-LR'!C27+'OccL2-DU-LR'!D27 -> 0.32808219 | D27: =+'OccL2-DU-LR'!E27+'OccL2-DU-LR'!F27 -> 0.15616438
... B39: 24 | C39: =+'OccL2-DU-LR'!C39+'OccL2-DU-LR'!D39 -> 1 | D39: =+'OccL2-DU-LR'!E39+'OccL2-DU-LR'!F39 -> 1
B45: DOE2.2 Schedule Format:
B47: $ Occupancy Schedule, average for all DAYUSE days of the year, all spaces
B48: =C15&"-DS"&" =DAY-SCHEDULE TYPE = FRACTION" -> Occ-DU-DS =DAY-SCHEDULE TYPE = FRACTION
B49: ="(1,24) ("&TEXT(C16,"0.0000")&","&TEXT(C17,"0.0000")&","&TEXT(C18,"0.0000")&","&TEXT(C19,"0.0000")&","&TEXT(C20,"0.0000")&","&TEXT(C21,"0.0000")&","&TEXT(C22,"0.0000")&","&TEXT(C23,"0.0000")&"," -> #VALUE!
B50: =" "&TEXT(C24,"0.0000")&","&TEXT(C25,"0.0000")&","&TEXT(C26,"0.0000")&","&TEXT(C27,"0.0000")&","&TEXT(C28,"0.0000")&","&TEXT(C29,"0.0000")&","&TEXT(C30,"0.0000")&","&TEXT(C31,"0.0000")&"," -> #VALUE!
B51: =" "&TEXT(C32,"0.0000")&","&TEXT(C33,"0.0000")&","&TEXT(C34,"0.0000")&","&TEXT(C35,"0.0000")&","&TEXT(C36,"0.0000")&","&TEXT(C37,"0.0000")&","&TEXT(C38,"0.0000")&","&TEXT(C39,"0.0000")&") .." -> #VALUE!
B53: $ Occupancy Schedule, average for all NON-DAYUSE days of the year, all spaces
B54: =D15&"-DS"&" =DAY-SCHEDULE TYPE = FRACTION" -> Occ-ND-DS =DAY-SCHEDULE TYPE = FRACTION
B55: ="(1,24) ("&TEXT(D16,"0.0000")&","&TEXT(D17,"0.0000")&","&TEXT(D18,"0.0000")&","&TEXT(D19,"0.0000")&","&TEXT(D20,"0.0000")&","&TEXT(D21,"0.0000")&","&TEXT(D22,"0.0000")&","&TEXT(D23,"0.0000")&"," -> #VALUE!
B56: =" "&TEXT(D24,"0.0000")&","&TEXT(D25,"0.0000")&","&TEXT(D26,"0.0000")&","&TEXT(D27,"0.0000")&","&TEXT(D28,"0.0000")&","&TEXT(D29,"0.0000")&","&TEXT(D30,"0.0000")&","&TEXT(D31,"0.0000")&"," -> #VALUE!
B57: =" "&TEXT(D32,"0.0000")&","&TEXT(D33,"0.0000")&","&TEXT(D34,"0.0000")&","&TEXT(D35,"0.0000")&","&TEXT(D36,"0.0000")&","&TEXT(D37,"0.0000")&","&TEXT(D38,"0.0000")&","&TEXT(D39,"0.0000")&") .." -> #VALUE!
B60: OCC-DU-WS = WEEK-SCHEDULE TYPE = FRACTION
B61: DAYS (ALL) DAY-SCHEDULE = Occ-DU-DS ..
B63: OCC-ND-WS = WEEK-SCHEDULE TYPE = FRACTION
B64: DAYS (ALL) DAY-SCHEDULE = Occ-ND-DS ..
B66: $ for Yr2000, Jan 1 is a Saturday
B67: $ week schedules alternate Day-Use and Non-Day-Use Schedules
B68: Occupancy-SCH = SCHEDULE TYPE = FRACTION
B69: THRU JAN 7 WEEK-SCHEDULE = OCC-DU-WS
...

Sheet Occ L1-LR
B2: Schedule Type: | D2: Occupancy | F2: Notes: | G2: This is the simplest schedule approriate for multi-zone house models.
B3: Detail Level: | D3: 1
B4: 1: | C4: Living Area | D4: Bedrooms
B8: Occupancy Schedule, where number of people = number of bedrooms
C9: Sensible load per person = 230 BTU/hr in the Living Areas, = 210 BTU/hr in the Bedrooms
C10: Latent load per person = 190 BTY/hr in the Living Areas, = 140 in the Bedrooms
C14: Living Area | D14: Bedrooms
B15: hour | C15: Occ-LR | D15: Occ-BR
B16: 1 | C16: =+'OccL2-DU-LR'!C16*Occupancy!$F$35+'OccL2-DU-LR'!E16*Occupancy!$F$36 -> 0 | D16: =+'OccL2-DU-LR'!D16*Occupancy!$F$35+'OccL2-DU-LR'!F16*Occupancy!$F$36 -> 1
B17: 2 | C17: =+'OccL2-DU-LR'!C17*Occupancy!$F$35+'OccL2-DU-LR'!E17*Occupancy!$F$36 -> 0 | D17: =+'OccL2-DU-LR'!D17*Occupancy!$F$35+'OccL2-DU-LR'!F17*Occupancy!$F$36 -> 1
B18: 3 | C18: =+'OccL2-DU-LR'!C18*Occupancy!$F$35+'OccL2-DU-LR'!E18*Occupancy!$F$36 -> 0 | D18: =+'OccL2-DU-LR'!D18*Occupancy!$F$35+'OccL2-DU-LR'!F18*Occupancy!$F$36 -> 1
B19: 4 | C19: =+'OccL2-DU-LR'!C19*Occupancy!$F$35+'OccL2-DU-LR'!E19*Occupancy!$F$36 -> 0 | D19: =+'OccL2-DU-LR'!D19*Occupancy!$F$35+'OccL2-DU-LR'!F19*Occupancy!$F$36 -> 1
B20: 5 | C20: =+'OccL2-DU-LR'!C20*Occupancy!$F$35+'OccL2-DU-LR'!E20*Occupancy!$F$36 -> 0 | D20: =+'OccL2-DU-LR'!D20*Occupancy!$F$35+'OccL2-DU-LR'!F20*Occupancy!$F$36 -> 1
B21: 6 | C21: =+'OccL2-DU-LR'!C21*Occupancy!$F$35+'OccL2-DU-LR'!E21*Occupancy!$F$36 -> 0 | D21: =+'OccL2-DU-LR'!D21*Occupancy!$F$35+'OccL2-DU-LR'!F21*Occupancy!$F$36 -> 1
B22: 7 | C22: =+'OccL2-DU-LR'!C22*Occupancy!$F$35+'OccL2-DU-LR'!E22*Occupancy!$F$36 -> 0.34383562 | D22: =+'OccL2-DU-LR'!D22*Occupancy!$F$35+'OccL2-DU-LR'!F22*Occupancy!$F$36 -> 0.65616438
B23: 8 | C23: =+'OccL2-DU-LR'!C23*Occupancy!$F$35+'OccL2-DU-LR'!E23*Occupancy!$F$36 -> 0.5 | D23: =+'OccL2-DU-LR'!D23*Occupancy!$F$35+'OccL2-DU-LR'!F23*Occupancy!$F$36 -> 0.38309589
B24: 9 | C24: =+'OccL2-DU-LR'!C24*Occupancy!$F$35+'OccL2-DU-LR'!E24*Occupancy!$F$36 -> 0.40860957 | D24: =+'OccL2-DU-LR'!D24*Occupancy!$F$35+'OccL2-DU-LR'!F24*Occupancy!$F$36 -> 0
B25: 10 | C25: =+'OccL2-DU-LR'!C25*Occupancy!$F$35+'OccL2-DU-LR'!E25*Occupancy!$F$36 -> 0.24188778 | D25: =+'OccL2-DU-LR'!D25*Occupancy!$F$35+'OccL2-DU-LR'!F25*Occupancy!$F$36 -> 0
B26: 11 | C26: =+'OccL2-DU-LR'!C26*Occupancy!$F$35+'OccL2-DU-LR'!E26*Occupancy!$F$36 -> 0.24188778 | D26: =+'OccL2-DU-LR'!D26*Occupancy!$F$35+'OccL2-DU-LR'!F26*Occupancy!$F$36 -> 0
B27: 12 | C27: =+'OccL2-DU-LR'!C27*Occupancy!$F$35+'OccL2-DU-LR'!E27*Occupancy!$F$36 -> 0.24188778 | D27: =+'OccL2-DU-LR'!D27*Occupancy!$F$35+'OccL2-DU-LR'!F27*Occupancy!$F$36 -> 0
... B39: 24 | C39: =+'OccL2-DU-LR'!C39*Occupancy!$F$35+'OccL2-DU-LR'!E39*Occupancy!$F$36 -> 0 | D39: =+'OccL2-DU-LR'!D39*Occupancy!$F$35+'OccL2-DU-LR'!F39*Occupancy!$F$36 -> 1
B45: DOE2.2 Schedule Format:
B47: $ Occupancy Schedule, average for all days of the year, LIVING SPACES ONLY
B48: =C15&"-DS"&" =DAY-SCHEDULE TYPE = FRACTION" -> Occ-LR-DS =DAY-SCHEDULE TYPE = FRACTION
B49: ="(1,24) ("&TEXT(C16,"0.0000")&","&TEXT(C17,"0.0000")&","&TEXT(C18,"0.0000")&","&TEXT(C19,"0.0000")&","&TEXT(C20,"0.0000")&","&TEXT(C21,"0.0000")&","&TEXT(C22,"0.0000")&","&TEXT(C23,"0.0000")&"," -> #VALUE!
B50: =" "&TEXT(C24,"0.0000")&","&TEXT(C25,"0.0000")&","&TEXT(C26,"0.0000")&","&TEXT(C27,"0.0000")&","&TEXT(C28,"0.0000")&","&TEXT(C29,"0.0000")&","&TEXT(C30,"0.0000")&","&TEXT(C31,"0.0000")&"," -> #VALUE!
B51: =" "&TEXT(C32,"0.0000")&","&TEXT(C33,"0.0000")&","&TEXT(C34,"0.0000")&","&TEXT(C35,"0.0000")&","&TEXT(C36,"0.0000")&","&TEXT(C37,"0.0000")&","&TEXT(C38,"0.0000")&","&TEXT(C39,"0.0000")&") .." -> #VALUE!
B53: =C15&"-SCH =SCHEDULE TYPE = FRACTION" -> Occ-LR-SCH =SCHEDULE TYPE = FRACTION
B54: =" THRU DEC 31 (ALL) "&C15&"-DS .." -> THRU DEC 31 (ALL) Occ-LR-DS ..
B57: $ Occupancy Schedule, average for all days of the year, BEDROOM SPACES ONLY
B58: =D15&"-DS"&" =DAY-SCHEDULE TYPE = FRACTION" -> Occ-BR-DS =DAY-SCHEDULE TYPE = FRACTION
B59: ="(1,24) ("&TEXT(D16,"0.0000")&","&TEXT(D17,"0.0000")&","&TEXT(D18,"0.0000")&","&TEXT(D19,"0.0000")&","&TEXT(D20,"0.0000")&","&TEXT(D21,"0.0000")&","&TEXT(D22,"0.0000")&","&TEXT(D23,"0.0000")&"," -> #VALUE!
B60: =" "&TEXT(D24,"0.0000")&","&TEXT(D25,"0.0000")&","&TEXT(D26,"0.0000")&","&TEXT(D27,"0.0000")&","&TEXT(D28,"0.0000")&","&TEXT(D29,"0.0000")&","&TEXT(D30,"0.0000")&","&TEXT(D31,"0.0000")&"," -> #VALUE!
B61: =" "&TEXT(D32,"0.0000")&","&TEXT(D33,"0.0000")&","&TEXT(D34,"0.0000")&","&TEXT(D35,"0.0000")&","&TEXT(D36,"0.0000")&","&TEXT(D37,"0.0000")&","&TEXT(D38,"0.0000")&","&TEXT(D39,"0.0000")&") .." -> #VALUE!
B63: =D15&"-SCH =SCHEDULE TYPE = FRACTION" -> Occ-BR-SCH =SCHEDULE TYPE = FRACTION
B64: =" THRU DEC 31 (ALL) "&D15&"-DS .." -> THRU DEC 31 (ALL) Occ-BR-DS ..

Sheet OccL2-WD-DU
B2: Schedule Type: | D2: Occupancy | F2: Notes: | G2: This is the most detailed schedule appropriate for single-zone models.
B3: Detail Level: | D3: 2
B4: 1: | C4: Day Use | D4: NonDayUse
B5: 2: | C5: Weekday | D5: Weekend
C6: (Living area and bedroom areas are combined)
B9: Occupancy Schedule, where number of people = number of bedrooms
C10: Sensible load per person = | F10: =+(Occupancy!F19*Occupancy!F38+Occupancy!F20*Occupancy!F39)/(Occupancy!F38+Occupancy!F39) -> 219.66429 | G10: BTU/hr/person | I10: (these values weighted by sum of Living area schedule and Bedroom area schedule)
C11: Latent load per person = | F11: =+(Occupancy!F22*Occupancy!F19+Occupancy!F23*Occupancy!F20)/(Occupancy!F19+Occupancy!F20) -> 166.13636 | G11: BTU/hr/person
C13: Day-Use | E13: No Day-Use
C14: Weekday | D14: Weekend | E14: Weekday | F14: Weekend
B15: hour | C15: Occ-DU-WD | D15: Occ-DU-WE | E15: Occ-ND-WD | F15: Occ-ND-WE
B16: 1 | C16: =+'Occ L3-WD-DU-LR'!C16+'Occ L3-WD-DU-LR'!D16 -> 1 | D16: =+'Occ L3-WD-DU-LR'!E16+'Occ L3-WD-DU-LR'!F16 -> 1 | E16: =+'Occ L3-WD-DU-LR'!H16+'Occ L3-WD-DU-LR'!I16 -> 1 | F16: =+'Occ L3-WD-DU-LR'!J16+'Occ L3-WD-DU-LR'!K16 -> 1
B17: 2 | C17: =+'Occ L3-WD-DU-LR'!C17+'Occ L3-WD-DU-LR'!D17 -> 1 | D17: =+'Occ L3-WD-DU-LR'!E17+'Occ L3-WD-DU-LR'!F17 -> 1 | E17: =+'Occ L3-WD-DU-LR'!H17+'Occ L3-WD-DU-LR'!I17 -> 1 | F17: =+'Occ L3-WD-DU-LR'!J17+'Occ L3-WD-DU-LR'!K17 -> 1
B18: 3 | C18: =+'Occ L3-WD-DU-LR'!C18+'Occ L3-WD-DU-LR'!D18 -> 1 | D18: =+'Occ L3-WD-DU-LR'!E18+'Occ L3-WD-DU-LR'!F18 -> 1 | E18: =+'Occ L3-WD-DU-LR'!H18+'Occ L3-WD-DU-LR'!I18 -> 1 | F18: =+'Occ L3-WD-DU-LR'!J18+'Occ L3-WD-DU-LR'!K18 -> 1
B19: 4 | C19: =+'Occ L3-WD-DU-LR'!C19+'Occ L3-WD-DU-LR'!D19 -> 1 | D19: =+'Occ L3-WD-DU-LR'!E19+'Occ L3-WD-DU-LR'!F19 -> 1 | E19: =+'Occ L3-WD-DU-LR'!H19+'Occ L3-WD-DU-LR'!I19 -> 1 | F19: =+'Occ L3-WD-DU-LR'!J19+'Occ L3-WD-DU-LR'!K19 -> 1
B20: 5 | C20: =+'Occ L3-WD-DU-LR'!C20+'Occ L3-WD-DU-LR'!D20 -> 1 | D20: =+'Occ L3-WD-DU-LR'!E20+'Occ L3-WD-DU-LR'!F20 -> 1 | E20: =+'Occ L3-WD-DU-LR'!H20+'Occ L3-WD-DU-LR'!I20 -> 1 | F20: =+'Occ L3-WD-DU-LR'!J20+'Occ L3-WD-DU-LR'!K20 -> 1
B21: 6 | C21: =+'Occ L3-WD-DU-LR'!C21+'Occ L3-WD-DU-LR'!D21 -> 1 | D21: =+'Occ L3-WD-DU-LR'!E21+'Occ L3-WD-DU-LR'!F21 -> 1 | E21: =+'Occ L3-WD-DU-LR'!H21+'Occ L3-WD-DU-LR'!I21 -> 1 | F21: =+'Occ L3-WD-DU-LR'!J21+'Occ L3-WD-DU-LR'!K21 -> 1
B22: 7 | C22: =+'Occ L3-WD-DU-LR'!C22+'Occ L3-WD-DU-LR'!D22 -> 1 | D22: =+'Occ L3-WD-DU-LR'!E22+'Occ L3-WD-DU-LR'!F22 -> 1 | E22: =+'Occ L3-WD-DU-LR'!H22+'Occ L3-WD-DU-LR'!I22 -> 1 | F22: =+'Occ L3-WD-DU-LR'!J22+'Occ L3-WD-DU-LR'!K22 -> 1
B23: 8 | C23: =+'Occ L3-WD-DU-LR'!C23+'Occ L3-WD-DU-LR'!D23 -> 0.83 | D23: =+'Occ L3-WD-DU-LR'!E23+'Occ L3-WD-DU-LR'!F23 -> 1 | E23: =+'Occ L3-WD-DU-LR'!H23+'Occ L3-WD-DU-LR'!I23 -> 0.83 | F23: =+'Occ L3-WD-DU-LR'!J23+'Occ L3-WD-DU-LR'!K23 -> 1
B24: 9 | C24: =+'Occ L3-WD-DU-LR'!C24+'Occ L3-WD-DU-LR'!D24 -> 0.33 | D24: =+'Occ L3-WD-DU-LR'!E24+'Occ L3-WD-DU-LR'!F24 -> 0.67 | E24: =+'Occ L3-WD-DU-LR'!H24+'Occ L3-WD-DU-LR'!I24 -> 0.25 | F24: =+'Occ L3-WD-DU-LR'!J24+'Occ L3-WD-DU-LR'!K24 -> 0.67
B25: 10 | C25: =+'Occ L3-WD-DU-LR'!C25+'Occ L3-WD-DU-LR'!D25 -> 0.25 | D25: =-'Occ L3-WD-DU-LR'!E25-'Occ L3-WD-DU-LR'!F25 -> -0.5 | E25: =+'Occ L3-WD-DU-LR'!H25+'Occ L3-WD-DU-LR'!I25 -> 0 | F25: =+'Occ L3-WD-DU-LR'!J25+'Occ L3-WD-DU-LR'!K25 -> 0.5
B26: 11 | C26: =+'Occ L3-WD-DU-LR'!C26+'Occ L3-WD-DU-LR'!D26 -> 0.25 | D26: =+'Occ L3-WD-DU-LR'!E26+'Occ L3-WD-DU-LR'!F26 -> 0.5 | E26: =+'Occ L3-WD-DU-LR'!H26+'Occ L3-WD-DU-LR'!I26 -> 0 | F26: =+'Occ L3-WD-DU-LR'!J26+'Occ L3-WD-DU-LR'!K26 -> 0.5
B27: 12 | C27: =+'Occ L3-WD-DU-LR'!C27+'Occ L3-WD-DU-LR'!D27 -> 0.25 | D27: =+'Occ L3-WD-DU-LR'!E27+'Occ L3-WD-DU-LR'!F27 -> 0.5 | E27: =+'Occ L3-WD-DU-LR'!H27+'Occ L3-WD-DU-LR'!I27 -> 0 | F27: =+'Occ L3-WD-DU-LR'!J27+'Occ L3-WD-DU-LR'!K27 -> 0.5
B28: 13 | C28: =+'Occ L3-WD-DU-LR'!C28+'Occ L3-WD-DU-LR'!D28 -> 0.25 | D28: =+'Occ L3-WD-DU-LR'!E28+'Occ L3-WD-DU-LR'!F28 -> 0.5 | E28: =+'Occ L3-WD-DU-LR'!H28+'Occ L3-WD-DU-LR'!I28 -> 0 | F28: =+'Occ L3-WD-DU-LR'!J28+'Occ L3-WD-DU-LR'!K28 -> 0.5
B29: 14 | C29: =+'Occ L3-WD-DU-LR'!C29+'Occ L3-WD-DU-LR'!D29 -> 0.25 | D29: =+'Occ L3-WD-DU-LR'!E29+'Occ L3-WD-DU-LR'!F29 -> 0.5 | E29: =+'Occ L3-WD-DU-LR'!H29+'Occ L3-WD-DU-LR'!I29 -> 0 | F29: =+'Occ L3-WD-DU-LR'!J29+'Occ L3-WD-DU-LR'!K29 -> 0.5
B30: 15 | C30: =+'Occ L3-WD-DU-LR'!C30+'Occ L3-WD-DU-LR'!D30 -> 0.25 | D30: =+'Occ L3-WD-DU-LR'!E30+'Occ L3-WD-DU-LR'!F30 -> 0.5 | E30: =+'Occ L3-WD-DU-LR'!H30+'Occ L3-WD-DU-LR'!I30 -> 0 | F30: =+'Occ L3-WD-DU-LR'!J30+'Occ L3-WD-DU-LR'!K30 -> 0.5
B31: 16 | C31: =+'Occ L3-WD-DU-LR'!C31+'Occ L3-WD-DU-LR'!D31 -> 0.25 | D31: =+'Occ L3-WD-DU-LR'!E31+'Occ L3-WD-DU-LR'!F31 -> 0.5 | E31: =+'Occ L3-WD-DU-LR'!H31+'Occ L3-WD-DU-LR'!I31 -> 0 | F31: =+'Occ L3-WD-DU-LR'!J31+'Occ L3-WD-DU-LR'!K31 -> 0.5
B32: 17 | C32: =+'Occ L3-WD-DU-LR'!C32+'Occ L3-WD-DU-LR'!D32 -> 0.25 | D32: =+'Occ L3-WD-DU-LR'!E32+'Occ L3-WD-DU-LR'!F32 -> 0.67 | E32: =+'Occ L3-WD-DU-LR'!H32+'Occ L3-WD-DU-LR'!I32 -> 0 | F32: =+'Occ L3-WD-DU-LR'!J32+'Occ L3-WD-DU-LR'!K32 -> 0.67
B33: 18 | C33: =+'Occ L3-WD-DU-LR'!C33+'Occ L3-WD-DU-LR'!D33 -> 0.5 | D33: =+'Occ L3-WD-DU-LR'!E33+'Occ L3-WD-DU-LR'!F33 -> 0.67 | E33: =+'Occ L3-WD-DU-LR'!H33+'Occ L3-WD-DU-LR'!I33 -> 0.5 | F33: =+'Occ L3-WD-DU-LR'!J33+'Occ L3-WD-DU-LR'!K33 -> 0.67
B34: 19 | C34: =+'Occ L3-WD-DU-LR'!C34+'Occ L3-WD-DU-LR'!D34 -> 1 | D34: =+'Occ L3-WD-DU-LR'!E34+'Occ L3-WD-DU-LR'!F34 -> 0.67 | E34: =+'Occ L3-WD-DU-LR'!H34+'Occ L3-WD-DU-LR'!I34 -> 1 | F34: =+'Occ L3-WD-DU-LR'!J34+'Occ L3-WD-DU-LR'!K34 -> 0.67
B35: 20 | C35: =+'Occ L3-WD-DU-LR'!C35+'Occ L3-WD-DU-LR'!D35 -> 1 | D35: =+'Occ L3-WD-DU-LR'!E35+'Occ L3-WD-DU-LR'!F35 -> 0.67 | E35: =+'Occ L3-WD-DU-LR'!H35+'Occ L3-WD-DU-LR'!I35 -> 1 | F35: =+'Occ L3-WD-DU-LR'!J35+'Occ L3-WD-DU-LR'!K35 -> 0.67
B36: 21 | C36: =+'Occ L3-WD-DU-LR'!C36+'Occ L3-WD-DU-LR'!D36 -> 1 | D36: =+'Occ L3-WD-DU-LR'!E36+'Occ L3-WD-DU-LR'!F36 -> 0.67 | E36: =+'Occ L3-WD-DU-LR'!H36+'Occ L3-WD-DU-LR'!I36 -> 1 | F36: =+'Occ L3-WD-DU-LR'!J36+'Occ L3-WD-DU-LR'!K36 -> 0.67
B37: 22 | C37: =+'Occ L3-WD-DU-LR'!C37+'Occ L3-WD-DU-LR'!D37 -> 1 | D37: =+'Occ L3-WD-DU-LR'!E37+'Occ L3-WD-DU-LR'!F37 -> 1 | E37: =+'Occ L3-WD-DU-LR'!H37+'Occ L3-WD-DU-LR'!I37 -> 1 | F37: =+'Occ L3-WD-DU-LR'!J37+'Occ L3-WD-DU-LR'!K37 -> 1
... B39: 24 | C39: =+'Occ L3-WD-DU-LR'!C39+'Occ L3-WD-DU-LR'!D39 -> 1 | D39: =+'Occ L3-WD-DU-LR'!E39+'Occ L3-WD-DU-LR'!F39 -> 1 | E39: =+'Occ L3-WD-DU-LR'!H39+'Occ L3-WD-DU-LR'!I39 -> 1 | F39: =+'Occ L3-WD-DU-LR'!J39+'Occ L3-WD-DU-LR'!K39 -> 1
B45: DOE2.2 Schedule Format:
B47: $ Occupancy Schedule, average for all WEEKDAYS of the year, DAYUSE Only
B48: =C15&"-DS"&" =DAY-SCHEDULE TYPE = FRACTION" -> Occ-DU-WD-DS =DAY-SCHEDULE TYPE = FRACTION
B49: ="(1,24) ("&TEXT(C16,"0.0000")&","&TEXT(C17,"0.0000")&","&TEXT(C18,"0.0000")&","&TEXT(C19,"0.0000")&","&TEXT(C20,"0.0000")&","&TEXT(C21,"0.0000")&","&TEXT(C22,"0.0000")&","&TEXT(C23,"0.0000")&"," -> #VALUE!
B50: =" "&TEXT(C24,"0.0000")&","&TEXT(C25,"0.0000")&","&TEXT(C26,"0.0000")&","&TEXT(C27,"0.0000")&","&TEXT(C28,"0.0000")&","&TEXT(C29,"0.0000")&","&TEXT(C30,"0.0000")&","&TEXT(C31,"0.0000")&"," -> #VALUE!
B51: =" "&TEXT(C32,"0.0000")&","&TEXT(C33,"0.0000")&","&TEXT(C34,"0.0000")&","&TEXT(C35,"0.0000")&","&TEXT(C36,"0.0000")&","&TEXT(C37,"0.0000")&","&TEXT(C38,"0.0000")&","&TEXT(C39,"0.0000")&") .." -> #VALUE!
...

Sheet Occ L2-WD-LR
B2: Schedule Type: | D2: Occupancy | F2: Notes: | G2: Use only with multi-zone house models.
B3: Detail Level: | D3: 2
B4: 1: | C4: Living Area | D4: Bedrooms
B5: 2: | C5: Weekday | D5: Weekend
C6: (Day use and non-Day use are combined)
B9: Occupancy Schedule, where number of people = number of bedrooms
C10: Sensible load per person = 230 BTU/hr in the Living Areas, = 210 BTU/hr in the Bedrooms
C11: Latent load per person = 190 BTY/hr in the Living Areas, = 140 in the Bedrooms
C13: Weekday | E13: Weekend
C14: Living Area | D14: Bedrooms | E14: Living Area | F14: Bedrooms
C15: Occ-LR-WD | D15: Occ-BR-WD | E15: Occ-LR-WE | F15: Occ-BR-WE
B16: 1 | C16: =+'Occ L3-WD-DU-LR'!C16*Occupancy!$F$35+'Occ L3-WD-DU-LR'!H16*Occupancy!$F$36 -> 0 | D16: =+'Occ L3-WD-DU-LR'!D16*Occupancy!$F$35+'Occ L3-WD-DU-LR'!I16*Occupancy!$F$36 -> 1 | E16: =+'Occ L3-WD-DU-LR'!E16*Occupancy!$F$35+'Occ L3-WD-DU-LR'!J16*Occupancy!$F$36 -> 0 | F16: =+'Occ L3-WD-DU-LR'!F16*Occupancy!$F$35+'Occ L3-WD-DU-LR'!K16*Occupancy!$F$36 -> 1
B17: 2 | C17: =+'Occ L3-WD-DU-LR'!C17*Occupancy!$F$35+'Occ L3-WD-DU-LR'!H17*Occupancy!$F$36 -> 0 | D17: =+'Occ L3-WD-DU-LR'!D17*Occupancy!$F$35+'Occ L3-WD-DU-LR'!I17*Occupancy!$F$36 -> 1 | E17: =+'Occ L3-WD-DU-LR'!E17*Occupancy!$F$35+'Occ L3-WD-DU-LR'!J17*Occupancy!$F$36 -> 0 | F17: =+'Occ L3-WD-DU-LR'!F17*Occupancy!$F$35+'Occ L3-WD-DU-LR'!K17*Occupancy!$F$36 -> 1
B18: 3 | C18: =+'Occ L3-WD-DU-LR'!C18*Occupancy!$F$35+'Occ L3-WD-DU-LR'!H18*Occupancy!$F$36 -> 0 | D18: =+'Occ L3-WD-DU-LR'!D18*Occupancy!$F$35+'Occ L3-WD-DU-LR'!I18*Occupancy!$F$36 -> 1 | E18: =+'Occ L3-WD-DU-LR'!E18*Occupancy!$F$35+'Occ L3-WD-DU-LR'!J18*Occupancy!$F$36 -> 0 | F18: =+'Occ L3-WD-DU-LR'!F18*Occupancy!$F$35+'Occ L3-WD-DU-LR'!K18*Occupancy!$F$36 -> 1
B19: 4 | C19: =+'Occ L3-WD-DU-LR'!C19*Occupancy!$F$35+'Occ L3-WD-DU-LR'!H19*Occupancy!$F$36 -> 0 | D19: =+'Occ L3-WD-DU-LR'!D19*Occupancy!$F$35+'Occ L3-WD-DU-LR'!I19*Occupancy!$F$36 -> 1 | E19: =+'Occ L3-WD-DU-LR'!E19*Occupancy!$F$35+'Occ L3-WD-DU-LR'!J19*Occupancy!$F$36 -> 0 | F19: =+'Occ L3-WD-DU-LR'!F19*Occupancy!$F$35+'Occ L3-WD-DU-LR'!K19*Occupancy!$F$36 -> 1
B20: 5 | C20: =+'Occ L3-WD-DU-LR'!C20*Occupancy!$F$35+'Occ L3-WD-DU-LR'!H20*Occupancy!$F$36 -> 0 | D20: =+'Occ L3-WD-DU-LR'!D20*Occupancy!$F$35+'Occ L3-WD-DU-LR'!I20*Occupancy!$F$36 -> 1 | E20: =+'Occ L3-WD-DU-LR'!E20*Occupancy!$F$35+'Occ L3-WD-DU-LR'!J20*Occupancy!$F$36 -> 0 | F20: =+'Occ L3-WD-DU-LR'!F20*Occupancy!$F$35+'Occ L3-WD-DU-LR'!K20*Occupancy!$F$36 -> 1
B21: 6 | C21: =+'Occ L3-WD-DU-LR'!C21*Occupancy!$F$35+'Occ L3-WD-DU-LR'!H21*Occupancy!$F$36 -> 0 | D21: =+'Occ L3-WD-DU-LR'!D21*Occupancy!$F$35+'Occ L3-WD-DU-LR'!I21*Occupancy!$F$36 -> 1 | E21: =+'Occ L3-WD-DU-LR'!E21*Occupancy!$F$35+'Occ L3-WD-DU-LR'!J21*Occupancy!$F$36 -> 0 | F21: =+'Occ L3-WD-DU-LR'!F21*Occupancy!$F$35+'Occ L3-WD-DU-LR'!K21*Occupancy!$F$36 -> 1
B22: 7 | C22: =+'Occ L3-WD-DU-LR'!C22*Occupancy!$F$35+'Occ L3-WD-DU-LR'!H22*Occupancy!$F$36 -> 0.5 | D22: =+'Occ L3-WD-DU-LR'!D22*Occupancy!$F$35+'Occ L3-WD-DU-LR'!I22*Occupancy!$F$36 -> 0.5 | E22: =+'Occ L3-WD-DU-LR'!E22*Occupancy!$F$35+'Occ L3-WD-DU-LR'!J22*Occupancy!$F$36 -> 0 | F22: =+'Occ L3-WD-DU-LR'!F22*Occupancy!$F$35+'Occ L3-WD-DU-LR'!K22*Occupancy!$F$36 -> 1
B23: 8 | C23: =+'Occ L3-WD-DU-LR'!C23*Occupancy!$F$35+'Occ L3-WD-DU-LR'!H23*Occupancy!$F$36 -> 0.5 | D23: =+'Occ L3-WD-DU-LR'!D23*Occupancy!$F$35+'Occ L3-WD-DU-LR'!I23*Occupancy!$F$36 -> 0.33 | E23: =+'Occ L3-WD-DU-LR'!E23*Occupancy!$F$35+'Occ L3-WD-DU-LR'!J23*Occupancy!$F$36 -> 0.5 | F23: =+'Occ L3-WD-DU-LR'!F23*Occupancy!$F$35+'Occ L3-WD-DU-LR'!K23*Occupancy!$F$36 -> 0.5
B24: 9 | C24: =+'Occ L3-WD-DU-LR'!C24*Occupancy!$F$35+'Occ L3-WD-DU-LR'!H24*Occupancy!$F$36 -> 0.28989041 | D24: =+'Occ L3-WD-DU-LR'!D24*Occupancy!$F$35+'Occ L3-WD-DU-LR'!I24*Occupancy!$F$36 -> 0 | E24: =+'Occ L3-WD-DU-LR'!E24*Occupancy!$F$35+'Occ L3-WD-DU-LR'!J24*Occupancy!$F$36 -> 0.67 | F24: =+'Occ L3-WD-DU-LR'!F24*Occupancy!$F$35+'Occ L3-WD-DU-LR'!K24*Occupancy!$F$36 -> 0
B25: 10 | C25: =+'Occ L3-WD-DU-LR'!C25*Occupancy!$F$35+'Occ L3-WD-DU-LR'!H25*Occupancy!$F$36 -> 0.12465753 | D25: =+'Occ L3-WD-DU-LR'!D25*Occupancy!$F$35+'Occ L3-WD-DU-LR'!I25*Occupancy!$F$36 -> 0 | E25: =+'Occ L3-WD-DU-LR'!E25*Occupancy!$F$35+'Occ L3-WD-DU-LR'!J25*Occupancy!$F$36 -> 0.5 | F25: =+'Occ L3-WD-DU-LR'!F25*Occupancy!$F$35+'Occ L3-WD-DU-LR'!K25*Occupancy!$F$36 -> 0
B26: 11 | C26: =+'Occ L3-WD-DU-LR'!C26*Occupancy!$F$35+'Occ L3-WD-DU-LR'!H26*Occupancy!$F$36 -> 0.12465753 | D26: =+'Occ L3-WD-DU-LR'!D26*Occupancy!$F$35+'Occ L3-WD-DU-LR'!I26*Occupancy!$F$36 -> 0 | E26: =+'Occ L3-WD-DU-LR'!E26*Occupancy!$F$35+'Occ L3-WD-DU-LR'!J26*Occupancy!$F$36 -> 0.5 | F26: =+'Occ L3-WD-DU-LR'!F26*Occupancy!$F$35+'Occ L3-WD-DU-LR'!K26*Occupancy!$F$36 -> 0
B27: 12 | C27: =+'Occ L3-WD-DU-LR'!C27*Occupancy!$F$35+'Occ L3-WD-DU-LR'!H27*Occupancy!$F$36 -> 0.12465753 | D27: =+'Occ L3-WD-DU-LR'!D27*Occupancy!$F$35+'Occ L3-WD-DU-LR'!I27*Occupancy!$F$36 -> 0 | E27: =+'Occ L3-WD-DU-LR'!E27*Occupancy!$F$35+'Occ L3-WD-DU-LR'!J27*Occupancy!$F$36 -> 0.5 | F27: =+'Occ L3-WD-DU-LR'!F27*Occupancy!$F$35+'Occ L3-WD-DU-LR'!K27*Occupancy!$F$36 -> 0
... B39: 24 | C39: =+'Occ L3-WD-DU-LR'!C39*Occupancy!$F$35+'Occ L3-WD-DU-LR'!H39*Occupancy!$F$36 -> 0 | D39: =+'Occ L3-WD-DU-LR'!D39*Occupancy!$F$35+'Occ L3-WD-DU-LR'!I39*Occupancy!$F$36 -> 1 | E39: =+'Occ L3-WD-DU-LR'!E39*Occupancy!$F$35+'Occ L3-WD-DU-LR'!J39*Occupancy!$F$36 -> 0 | F39: =+'Occ L3-WD-DU-LR'!F39*Occupancy!$F$35+'Occ L3-WD-DU-LR'!K39*Occupancy!$F$36 -> 1
B45: DOE2.2 Schedule Format:
B47: $ Occupancy Schedule, average for all WEEKDAYS of the year, DAYUSE Only
B48: =C15&"-DS"&" =DAY-SCHEDULE TYPE = FRACTION" -> Occ-LR-WD-DS =DAY-SCHEDULE TYPE = FRACTION
B49: ="(1,24) ("&TEXT(C16,"0.0000")&","&TEXT(C17,"0.0000")&","&TEXT(C18,"0.0000")&","&TEXT(C19,"0.0000")&","&TEXT(C20,"0.0000")&","&TEXT(C21,"0.0000")&","&TEXT(C22,"0.0000")&","&TEXT(C23,"0.0000")&"," -> #VALUE!
B50: =" "&TEXT(C24,"0.0000")&","&TEXT(C25,"0.0000")&","&TEXT(C26,"0.0000")&","&TEXT(C27,"0.0000")&","&TEXT(C28,"0.0000")&","&TEXT(C29,"0.0000")&","&TEXT(C30,"0.0000")&","&TEXT(C31,"0.0000")&"," -> #VALUE!
B51: =" "&TEXT(C32,"0.0000")&","&TEXT(C33,"0.0000")&","&TEXT(C34,"0.0000")&","&TEXT(C35,"0.0000")&","&TEXT(C36,"0.0000")&","&TEXT(C37,"0.0000")&","&TEXT(C38,"0.0000")&","&TEXT(C39,"0.0000")&") .." -> #VALUE!
B53: $ Occupancy Schedule, average for all WEEKEND days of the year, DAYUSE Only
B54: =D15&"-DS"&" =DAY-SCHEDULE TYPE = FRACTION" -> Occ-BR-WD-DS =DAY-SCHEDULE TYPE = FRACTION
B55: ="(1,24) ("&TEXT(D16,"0.0000")&","&TEXT(D17,"0.0000")&","&TEXT(D18,"0.0000")&","&TEXT(D19,"0.0000")&","&TEXT(D20,"0.0000")&","&TEXT(D21,"0.0000")&","&TEXT(D22,"0.0000")&","&TEXT(D23,"0.0000")&"," -> #VALUE!
B56: =" "&TEXT(D24,"0.0000")&","&TEXT(D25,"0.0000")&","&TEXT(D26,"0.0000")&","&TEXT(D27,"0.0000")&","&TEXT(D28,"0.0000")&","&TEXT(D29,"0.0000")&","&TEXT(D30,"0.0000")&","&TEXT(D31,"0.0000")&"," -> #VALUE!
B57: =" "&TEXT(D32,"0.0000")&","&TEXT(D33,"0.0000")&","&TEXT(D34,"0.0000")&","&TEXT(D35,"0.0000")&","&TEXT(D36,"0.0000")&","&TEXT(D37,"0.0000")&","&TEXT(D38,"0.0000")&","&TEXT(D39,"0.0000")&") .." -> #VALUE!
B59: $ Occupancy Schedule, average for all WEEKDAYS of the year, NON-DAYUSE Only
B60: =E15&"-DS"&" =DAY-SCHEDULE TYPE = FRACTION" -> Occ-LR-WE-DS =DAY-SCHEDULE TYPE = FRACTION
B61: ="(1,24) ("&TEXT(E16,"0.0000")&","&TEXT(E17,"0.0000")&","&TEXT(E18,"0.0000")&","&TEXT(E19,"0.0000")&","&TEXT(E20,"0.0000")&","&TEXT(E21,"0.0000")&","&TEXT(E22,"0.0000")&","&TEXT(E23,"0.0000")&"," -> #VALUE!
B62: =" "&TEXT(E24,"0.0000")&","&TEXT(E25,"0.0000")&","&TEXT(E26,"0.0000")&","&TEXT(E27,"0.0000")&","&TEXT(E28,"0.0000")&","&TEXT(E29,"0.0000")&","&TEXT(E30,"0.0000")&","&TEXT(E31,"0.0000")&"," -> #VALUE!
B63: =" "&TEXT(E32,"0.0000")&","&TEXT(E33,"0.0000")&","&TEXT(E34,"0.0000")&","&TEXT(E35,"0.0000")&","&TEXT(E36,"0.0000")&","&TEXT(E37,"0.0000")&","&TEXT(E38,"0.0000")&","&TEXT(E39,"0.0000")&") .." -> #VALUE!
...

Sheet OccL2-DU-LR
B2: Schedule Type: | D2: Occupancy | F2: Notes: | G2: Limited applicability (if only 2 day-types are allowed, use weekday vs. weekend)
B3: Detail Level: | D3: 2 | G3: Use only with multi-zone house models.
B4: 1: | C4: Living Area | D4: Bedrooms
B5: 2: | C5: Day Use | D5: NonDayUse
C6: (weekdays and weekends are combined)
B9: Occupancy Schedule, where number of people = number of bedrooms
C10: Sensible load per person = 230 BTU/hr in the Living Areas, = 210 BTU/hr in the Bedrooms
C11: Latent load per person = 190 BTY/hr in the Living Areas, = 140 in the Bedrooms
C13: Day-Use | E13: No Day-Use
C14: Living Area | D14: Bedrooms | E14: Living Area | F14: Bedrooms
B15: hour | C15: Occ-DU-LR | D15: Occ-DU-BR | E15: Occ-ND-LR | F15: Occ-ND-BR
B16: 1 | C16: =+'Occ L3-WD-DU-LR'!C16*Occupancy!$F$34+'Occ L3-WD-DU-LR'!E16*Occupancy!$F$33 -> 0 | D16: =+'Occ L3-WD-DU-LR'!D16*Occupancy!$F$34+'Occ L3-WD-DU-LR'!F16*Occupancy!$F$33 -> 1 | E16: =+'Occ L3-WD-DU-LR'!H16*Occupancy!$F$34+'Occ L3-WD-DU-LR'!J16*Occupancy!$F$33 -> 0 | F16: =+'Occ L3-WD-DU-LR'!I16*Occupancy!$F$34+'Occ L3-WD-DU-LR'!K16*Occupancy!$F$33 -> 1
B17: 2 | C17: =+'Occ L3-WD-DU-LR'!C17*Occupancy!$F$34+'Occ L3-WD-DU-LR'!E17*Occupancy!$F$33 -> 0 | D17: =+'Occ L3-WD-DU-LR'!D17*Occupancy!$F$34+'Occ L3-WD-DU-LR'!F17*Occupancy!$F$33 -> 1 | E17: =+'Occ L3-WD-DU-LR'!H17*Occupancy!$F$34+'Occ L3-WD-DU-LR'!J17*Occupancy!$F$33 -> 0 | F17: =+'Occ L3-WD-DU-LR'!I17*Occupancy!$F$34+'Occ L3-WD-DU-LR'!K17*Occupancy!$F$33 -> 1
B18: 3 | C18: =+'Occ L3-WD-DU-LR'!C18*Occupancy!$F$34+'Occ L3-WD-DU-LR'!E18*Occupancy!$F$33 -> 0 | D18: =+'Occ L3-WD-DU-LR'!D18*Occupancy!$F$34+'Occ L3-WD-DU-LR'!F18*Occupancy!$F$33 -> 1 | E18: =+'Occ L3-WD-DU-LR'!H18*Occupancy!$F$34+'Occ L3-WD-DU-LR'!J18*Occupancy!$F$33 -> 0 | F18: =+'Occ L3-WD-DU-LR'!I18*Occupancy!$F$34+'Occ L3-WD-DU-LR'!K18*Occupancy!$F$33 -> 1
B19: 4 | C19: =+'Occ L3-WD-DU-LR'!C19*Occupancy!$F$34+'Occ L3-WD-DU-LR'!E19*Occupancy!$F$33 -> 0 | D19: =+'Occ L3-WD-DU-LR'!D19*Occupancy!$F$34+'Occ L3-WD-DU-LR'!F19*Occupancy!$F$33 -> 1 | E19: =+'Occ L3-WD-DU-LR'!H19*Occupancy!$F$34+'Occ L3-WD-DU-LR'!J19*Occupancy!$F$33 -> 0 | F19: =+'Occ L3-WD-DU-LR'!I19*Occupancy!$F$34+'Occ L3-WD-DU-LR'!K19*Occupancy!$F$33 -> 1
B20: 5 | C20: =+'Occ L3-WD-DU-LR'!C20*Occupancy!$F$34+'Occ L3-WD-DU-LR'!E20*Occupancy!$F$33 -> 0 | D20: =+'Occ L3-WD-DU-LR'!D20*Occupancy!$F$34+'Occ L3-WD-DU-LR'!F20*Occupancy!$F$33 -> 1 | E20: =+'Occ L3-WD-DU-LR'!H20*Occupancy!$F$34+'Occ L3-WD-DU-LR'!J20*Occupancy!$F$33 -> 0 | F20: =+'Occ L3-WD-DU-LR'!I20*Occupancy!$F$34+'Occ L3-WD-DU-LR'!K20*Occupancy!$F$33 -> 1
B21: 6 | C21: =+'Occ L3-WD-DU-LR'!C21*Occupancy!$F$34+'Occ L3-WD-DU-LR'!E21*Occupancy!$F$33 -> 0 | D21: =+'Occ L3-WD-DU-LR'!D21*Occupancy!$F$34+'Occ L3-WD-DU-LR'!F21*Occupancy!$F$33 -> 1 | E21: =+'Occ L3-WD-DU-LR'!H21*Occupancy!$F$34+'Occ L3-WD-DU-LR'!J21*Occupancy!$F$33 -> 0 | F21: =+'Occ L3-WD-DU-LR'!I21*Occupancy!$F$34+'Occ L3-WD-DU-LR'!K21*Occupancy!$F$33 -> 1
B22: 7 | C22: =+'Occ L3-WD-DU-LR'!C22*Occupancy!$F$34+'Occ L3-WD-DU-LR'!E22*Occupancy!$F$33 -> 0.34383562 | D22: =+'Occ L3-WD-DU-LR'!D22*Occupancy!$F$34+'Occ L3-WD-DU-LR'!F22*Occupancy!$F$33 -> 0.65616438 | E22: =+'Occ L3-WD-DU-LR'!H22*Occupancy!$F$34+'Occ L3-WD-DU-LR'!J22*Occupancy!$F$33 -> 0.34383562 | F22: =+'Occ L3-WD-DU-LR'!I22*Occupancy!$F$34+'Occ L3-WD-DU-LR'!K22*Occupancy!$F$33 -> 0.65616438
B23: 8 | C23: =+'Occ L3-WD-DU-LR'!C23*Occupancy!$F$34+'Occ L3-WD-DU-LR'!E23*Occupancy!$F$33 -> 0.5 | D23: =+'Occ L3-WD-DU-LR'!D23*Occupancy!$F$34+'Occ L3-WD-DU-LR'!F23*Occupancy!$F$33 -> 0.38309589 | E23: =+'Occ L3-WD-DU-LR'!H23*Occupancy!$F$34+'Occ L3-WD-DU-LR'!J23*Occupancy!$F$33 -> 0.5 | F23: =+'Occ L3-WD-DU-LR'!I23*Occupancy!$F$34+'Occ L3-WD-DU-LR'!K23*Occupancy!$F$33 -> 0.38309589
B24: 9 | C24: =+'Occ L3-WD-DU-LR'!C24*Occupancy!$F$34+'Occ L3-WD-DU-LR'!E24*Occupancy!$F$33 -> 0.43619178 | D24: =+'Occ L3-WD-DU-LR'!D24*Occupancy!$F$34+'Occ L3-WD-DU-LR'!F24*Occupancy!$F$33 -> 0 | E24: =+'Occ L3-WD-DU-LR'!H24*Occupancy!$F$34+'Occ L3-WD-DU-LR'!J24*Occupancy!$F$33 -> 0.38117808 | F24: =+'Occ L3-WD-DU-LR'!I24*Occupancy!$F$34+'Occ L3-WD-DU-LR'!K24*Occupancy!$F$33 -> 0
B25: 10 | C25: =+'Occ L3-WD-DU-LR'!C25*Occupancy!$F$34+'Occ L3-WD-DU-LR'!E25*Occupancy!$F$33 -> 0.32808219 | D25: =+'Occ L3-WD-DU-LR'!D25*Occupancy!$F$34+'Occ L3-WD-DU-LR'!F25*Occupancy!$F$33 -> 0 | E25: =+'Occ L3-WD-DU-LR'!H25*Occupancy!$F$34+'Occ L3-WD-DU-LR'!J25*Occupancy!$F$33 -> 0.15616438 | F25: =+'Occ L3-WD-DU-LR'!I25*Occupancy!$F$34+'Occ L3-WD-DU-LR'!K25*Occupancy!$F$33 -> 0
B26: 11 | C26: =+'Occ L3-WD-DU-LR'!C26*Occupancy!$F$34+'Occ L3-WD-DU-LR'!E26*Occupancy!$F$33 -> 0.32808219 | D26: =+'Occ L3-WD-DU-LR'!D26*Occupancy!$F$34+'Occ L3-WD-DU-LR'!F26*Occupancy!$F$33 -> 0 | E26: =+'Occ L3-WD-DU-LR'!H26*Occupancy!$F$34+'Occ L3-WD-DU-LR'!J26*Occupancy!$F$33 -> 0.15616438 | F26: =+'Occ L3-WD-DU-LR'!I26*Occupancy!$F$34+'Occ L3-WD-DU-LR'!K26*Occupancy!$F$33 -> 0
B27: 12 | C27: =+'Occ L3-WD-DU-LR'!C27*Occupancy!$F$34+'Occ L3-WD-DU-LR'!E27*Occupancy!$F$33 -> 0.32808219 | D27: =+'Occ L3-WD-DU-LR'!D27*Occupancy!$F$34+'Occ L3-WD-DU-LR'!F27*Occupancy!$F$33 -> 0 | E27: =+'Occ L3-WD-DU-LR'!H27*Occupancy!$F$34+'Occ L3-WD-DU-LR'!J27*Occupancy!$F$33 -> 0.15616438 | F27: =+'Occ L3-WD-DU-LR'!I27*Occupancy!$F$34+'Occ L3-WD-DU-LR'!K27*Occupancy!$F$33 -> 0
... B39: 24 | C39: =+'Occ L3-WD-DU-LR'!C39*Occupancy!$F$34+'Occ L3-WD-DU-LR'!E39*Occupancy!$F$33 -> 0 | D39: =+'Occ L3-WD-DU-LR'!D39*Occupancy!$F$34+'Occ L3-WD-DU-LR'!F39*Occupancy!$F$33 -> 1 | E39: =+'Occ L3-WD-DU-LR'!H39*Occupancy!$F$34+'Occ L3-WD-DU-LR'!J39*Occupancy!$F$33 -> 0 | F39: =+'Occ L3-WD-DU-LR'!I39*Occupancy!$F$34+'Occ L3-WD-DU-LR'!K39*Occupancy!$F$33 -> 1
B45: DOE2.2 Schedule Format:
B47: $ Occupancy Schedule, average for all WEEKDAYS of the year, DAYUSE Only
B48: =C15&"-DS"&" =DAY-SCHEDULE TYPE = FRACTION" -> Occ-DU-LR-DS =DAY-SCHEDULE TYPE = FRACTION
B49: ="(1,24) ("&TEXT(C16,"0.0000")&","&TEXT(C17,"0.0000")&","&TEXT(C18,"0.0000")&","&TEXT(C19,"0.0000")&","&TEXT(C20,"0.0000")&","&TEXT(C21,"0.0000")&","&TEXT(C22,"0.0000")&","&TEXT(C23,"0.0000")&"," -> #VALUE!
B50: =" "&TEXT(C24,"0.0000")&","&TEXT(C25,"0.0000")&","&TEXT(C26,"0.0000")&","&TEXT(C27,"0.0000")&","&TEXT(C28,"0.0000")&","&TEXT(C29,"0.0000")&","&TEXT(C30,"0.0000")&","&TEXT(C31,"0.0000")&"," -> #VALUE!
B51: =" "&TEXT(C32,"0.0000")&","&TEXT(C33,"0.0000")&","&TEXT(C34,"0.0000")&","&TEXT(C35,"0.0000")&","&TEXT(C36,"0.0000")&","&TEXT(C37,"0.0000")&","&TEXT(C38,"0.0000")&","&TEXT(C39,"0.0000")&") .." -> #VALUE!
B53: $ Occupancy Schedule, average for all WEEKEND days of the year, DAYUSE Only
B54: =D15&"-DS"&" =DAY-SCHEDULE TYPE = FRACTION" -> Occ-DU-BR-DS =DAY-SCHEDULE TYPE = FRACTION
B55: ="(1,24) ("&TEXT(D16,"0.0000")&","&TEXT(D17,"0.0000")&","&TEXT(D18,"0.0000")&","&TEXT(D19,"0.0000")&","&TEXT(D20,"0.0000")&","&TEXT(D21,"0.0000")&","&TEXT(D22,"0.0000")&","&TEXT(D23,"0.0000")&"," -> #VALUE!
B56: =" "&TEXT(D24,"0.0000")&","&TEXT(D25,"0.0000")&","&TEXT(D26,"0.0000")&","&TEXT(D27,"0.0000")&","&TEXT(D28,"0.0000")&","&TEXT(D29,"0.0000")&","&TEXT(D30,"0.0000")&","&TEXT(D31,"0.0000")&"," -> #VALUE!
B57: =" "&TEXT(D32,"0.0000")&","&TEXT(D33,"0.0000")&","&TEXT(D34,"0.0000")&","&TEXT(D35,"0.0000")&","&TEXT(D36,"0.0000")&","&TEXT(D37,"0.0000")&","&TEXT(D38,"0.0000")&","&TEXT(D39,"0.0000")&") .." -> #VALUE!
B59: $ Occupancy Schedule, average for all WEEKDAYS of the year, NON-DAYUSE Only
B60: =E15&"-DS"&" =DAY-SCHEDULE TYPE = FRACTION" -> Occ-ND-LR-DS =DAY-SCHEDULE TYPE = FRACTION
B61: ="(1,24) ("&TEXT(E16,"0.0000")&","&TEXT(E17,"0.0000")&","&TEXT(E18,"0.0000")&","&TEXT(E19,"0.0000")&","&TEXT(E20,"0.0000")&","&TEXT(E21,"0.0000")&","&TEXT(E22,"0.0000")&","&TEXT(E23,"0.0000")&"," -> #VALUE!
B62: =" "&TEXT(E24,"0.0000")&","&TEXT(E25,"0.0000")&","&TEXT(E26,"0.0000")&","&TEXT(E27,"0.0000")&","&TEXT(E28,"0.0000")&","&TEXT(E29,"0.0000")&","&TEXT(E30,"0.0000")&","&TEXT(E31,"0.0000")&"," -> #VALUE!
B63: =" "&TEXT(E32,"0.0000")&","&TEXT(E33,"0.0000")&","&TEXT(E34,"0.0000")&","&TEXT(E35,"0.0000")&","&TEXT(E36,"0.0000")&","&TEXT(E37,"0.0000")&","&TEXT(E38,"0.0000")&","&TEXT(E39,"0.0000")&") .." -> #VALUE!
...

Sheet Occ L3-WD-DU-LR
B2: Schedule Type: | D2: Occupancy | F2: Notes: | G2: This is the most detailed schedule appropriate to mulit-zone house models.
B3: Detail Level: | D3: 3
B4: 1: | C4: Living Area | D4: Bedrooms
B5: 2: | C5: Day Use | D5: NonDayUse
B6: 3: | C6: Weekday | D6: Weekend
B8: Occupancy Schedule, where number of people = number of bedrooms
C9: Sensible load per person = 230 BTU/hr in the Living Areas, = 210 BTU/hr in the Bedrooms
C10: Latent load per person = 190 BTY/hr in the Living Areas, = 140 in the Bedrooms
C12: Day-Use | H12: No Day-Use
C13: Weekday | E13: Weekend | H13: Weekday | J13: Weekend
C14: LivingArea | D14: Bedrooms | E14: LivingArea | F14: Bedrooms | H14: LivingArea | I14: Bedrooms | J14: LivingArea | K14: Bedrooms
C15: Occ-DU-LR-WD | D15: Occ-DU-BR-WD | E15: Occ-DU-LR-WE | F15: Occ-DU-BR-WE | H15: Occ-ND-LR-WD | I15: Occ-ND-BR-WD | J15: Occ-ND-LR-WE | K15: Occ-ND-BR-WE
B16: 1 | C16: 0 | D16: 1 | E16: 0 | F16: 1 | H16: 0 | I16: 1 | J16: 0 | K16: 1
B17: 2 | C17: 0 | D17: 1 | E17: 0 | F17: 1 | H17: 0 | I17: 1 | J17: 0 | K17: 1
B18: 3 | C18: 0 | D18: 1 | E18: 0 | F18: 1 | H18: 0 | I18: 1 | J18: 0 | K18: 1
B19: 4 | C19: 0 | D19: 1 | E19: 0 | F19: 1 | H19: 0 | I19: 1 | J19: 0 | K19: 1
B20: 5 | C20: 0 | D20: 1 | E20: 0 | F20: 1 | H20: 0 | I20: 1 | J20: 0 | K20: 1
B21: 6 | C21: 0 | D21: 1 | E21: 0 | F21: 1 | H21: 0 | I21: 1 | J21: 0 | K21: 1
B22: 7 | C22: 0.5 | D22: 0.5 | E22: 0 | F22: 1 | H22: 0.5 | I22: 0.5 | J22: 0 | K22: 1
B23: 8 | C23: 0.5 | D23: 0.33 | E23: 0.5 | F23: 0.5 | H23: 0.5 | I23: 0.33 | J23: 0.5 | K23: 0.5
B24: 9 | C24: 0.33 | D24: 0 | E24: 0.67 | F24: 0 | H24: =+(H23+H25)/2 -> 0.25 | I24: 0 | J24: 0.67 | K24: 0
B25: 10 | C25: 0.25 | D25: 0 | E25: 0.5 | F25: 0 | H25: 0 | I25: 0 | J25: 0.5 | K25: 0
B26: 11 | C26: 0.25 | D26: 0 | E26: 0.5 | F26: 0 | H26: 0 | I26: 0 | J26: 0.5 | K26: 0
B27: 12 | C27: 0.25 | D27: 0 | E27: 0.5 | F27: 0 | H27: 0 | I27: 0 | J27: 0.5 | K27: 0
B28: 13 | C28: 0.25 | D28: 0 | E28: 0.5 | F28: 0 | H28: 0 | I28: 0 | J28: 0.5 | K28: 0
B29: 14 | C29: 0.25 | D29: 0 | E29: 0.5 | F29: 0 | H29: 0 | I29: 0 | J29: 0.5 | K29: 0
B30: 15 | C30: 0.25 | D30: 0 | E30: 0.5 | F30: 0 | H30: 0 | I30: 0 | J30: 0.5 | K30: 0
B31: 16 | C31: 0.25 | D31: 0 | E31: 0.5 | F31: 0 | H31: 0 | I31: 0 | J31: 0.5 | K31: 0
B32: 17 | C32: 0.25 | D32: 0 | E32: 0.67 | F32: 0 | H32: 0 | I32: 0 | J32: 0.67 | K32: 0
B33: 18 | C33: 0.5 | D33: 0 | E33: 0.67 | F33: 0 | H33: 0.5 | I33: 0 | J33: 0.67 | K33: 0
B34: 19 | C34: 1 | D34: 0 | E34: 0.67 | F34: 0 | H34: 1 | I34: 0 | J34: 0.67 | K34: 0
B35: 20 | C35: 1 | D35: 0 | E35: 0.67 | F35: 0 | H35: 1 | I35: 0 | J35: 0.67 | K35: 0
B36: 21 | C36: 1 | D36: 0 | E36: 0.67 | F36: 0 | H36: 1 | I36: 0 | J36: 0.67 | K36: 0
... B39: 24 | C39: 0 | D39: 1 | E39: 0 | F39: 1 | H39: 0 | I39: 1 | J39: 0 | K39: 1
B45: DOE2.2 Schedule Format:
B47: $ Occupancy Schedule, average for all WEEKDAYS of the year, DAYUSE Only, LIVING Areas
B48: =C15&"-DS"&" =DAY-SCHEDULE TYPE = FRACTION" -> Occ-DU-LR-WD-DS =DAY-SCHEDULE TYPE = FRACTION
B49: ="(1,24) ("&TEXT(C16,"0.0000")&","&TEXT(C17,"0.0000")&","&TEXT(C18,"0.0000")&","&TEXT(C19,"0.0000")&","&TEXT(C20,"0.0000")&","&TEXT(C21,"0.0000")&","&TEXT(C22,"0.0000")&","&TEXT(C23,"0.0000")&"," -> #VALUE!
B50: =" "&TEXT(C24,"0.0000")&","&TEXT(C25,"0.0000")&","&TEXT(C26,"0.0000")&","&TEXT(C27,"0.0000")&","&TEXT(C28,"0.0000")&","&TEXT(C29,"0.0000")&","&TEXT(C30,"0.0000")&","&TEXT(C31,"0.0000")&"," -> #VALUE!
B51: =" "&TEXT(C32,"0.0000")&","&TEXT(C33,"0.0000")&","&TEXT(C34,"0.0000")&","&TEXT(C35,"0.0000")&","&TEXT(C36,"0.0000")&","&TEXT(C37,"0.0000")&","&TEXT(C38,"0.0000")&","&TEXT(C39,"0.0000")&") .." -> #VALUE!
...
